Workbook
Name b: '[1]Data & Results'!$D$6
Name b: '[1]Data & Results'!$D$6
Name b: '[2]Data & Results'!$D$4
Name b: '[1]Data & Results'!$D$6
Name b: 'Data & Results'!$D$5
Name Ba: '[1]Data & Results'!$D$5
Name Ba: '[1]Data & Results'!$D$5
Name Ba: '[1]Data & Results'!$D$5
Name Ba: 'Data & Results'!$D$7
Name col: [2]Graph!$A$14
Name col: Graph!$A$14
Name D: '[2]Data & Results'!$D$4
Name D: #REF!
Name Da: '[2]Data & Results'!$D$6
Name gn: '[2]Data & Results'!$D$10
Name gn: 'Data & Results'!$D$11
Name hi: '[2]Data & Results'!$D$13
Name hi: 'Data & Results'!$D$14
Name k: '[2]Data & Results'!$D$8
Name k: 'Data & Results'!$D$9
Name L: '[2]Data & Results'!$D$5
Name L: 'Data & Results'!$D$6
Name nu: '[2]Data & Results'!$D$9
Name nu: 'Data & Results'!$D$10
Name Num: '[2]Data & Results'!$D$15
Name Num: 'Data & Results'!$D$16
Name p: '[3]Data & Results'!#REF!
Name p: '[3]Data & Results'!#REF!
Name p: '[3]Data & Results'!#REF!
Name p: '[3]Data & Results'!#REF!
Name p: '[3]Data & Results'!#REF!
Name p: '[3]Data & Results'!#REF!
Name Ratio: [2]Graph!$B$17
Name Ratio: Graph!$B$17
Name rho: '[2]Data & Results'!$D$7
Name rho: 'Data & Results'!$D$8
Name step: '[2]Data & Results'!$D$14
Name step: 'Data & Results'!$D$15
Name x: [1]Graph!$B$1

Sheet Rect flume Quality check
A1: Date | B1: Comments | C1: SIRIS l/s | D1: Refernece l/s | E1: Error | F1: Revision
A2: 11th May 2016 | B2: Updated to v3.1 and checked against BS/ISO Annexe D Flume 2 software B=500 b =200 L=1200 H=300 ks0.6mm | C2: 54.77 | D2: 53.1 | E2: =(C2-D2)/D2 -> 0.031450094 | F2: 3.1
A3: 11th May 2016 | B3: Checked against BS/ISO 4359:2013 example p55 Section 14.3 B-500 b=200 L=1200 ks=0.6mm | C3: 54.77 | D3: 54.9 | E3: =(C3-D3)/D3 -> -0.0023679417 | F3: 3.1
A4: 11th May 2016 | B4: Checked against BS/ISO Annexe D Flume 2 software B=200 b =100 L=600 H=300 ks0.6mm | C4: 28.21 | D4: 27.7 | E4: =(C4-D4)/D4 -> 0.018411552 | F4: 3.1
A5: 11th May 2016 | B5: Checked against Tyler-HR Wallingford (b=100 B=200 L=600 Ks=1.5 H=295mm) | C5: 27.5 | D5: 26.37 | E5: =(C5-D5)/D5 -> 0.042851725 | F5: 3.1

Sheet Input Data
A1: Appendix A - Survey Data (Tariff)
A3: Site Details | F3: Secondary Device
A4: Site name / flow location | C4: Ballyrickard WwTW | F4: Manufacturer | H4: Pulsar
A5: Consent Reference | C5: 2025/2006 | F5: Model | H5: Ultra 5
A6: Max Daily Volume M3 | C6: 31577 | F6: Serial no | H6: F261255
C7: M3/Day | D7: L/Sec | E7: M3/Hr | F7: MCERTS accredited? | H7: No
A8: Q Max Instrument | C8: =D8*86.4 -> 38993.184 | D8: 451.31 | E8: =C8/24 -> 1624.716 | F8: Telemetry U(t) | H8: 2
A9: FFT | C9: 31577 | D9: =C9/86.4 -> 365.47454 | E9: =C9/24 -> 1315.7083 | F9: Look Up Table U(lu) | H9: 1
A10: DWF | C10: 14778 | D10: =C10/86.4 -> 171.04167 | E10: =C10/24 -> 615.75 | F10: Include % Uncertainty above if required enter 0 if not required
A21: Measurement | C21: Approach Channel Width - B | G21: Throat Width - b
A22: Height | C22: 1 | D22: 2 | E22: 3 | F22: 4 | G22: 5 | H22: 6 | I22: 7 | J22: 8
A23: A | B23: (h Max) | C23: 1046 | D23: 1046 | E23: 1042 | F23: 1027 | G23: 650 | H23: 650 | I23: 652 | J23: 654
A24: B | B24: (.5h Max) | C24: 1046 | D24: 1047 | E24: 1043 | F24: 1029 | G24: 648 | H24: 650 | I24: 651 | J24: 654
A25: C | B25: (Zero) | C25: 1045 | D25: 1046 | E25: 1041 | F25: 1036 | G25: 649 | H25: 649 | I25: 650 | J25: 654
G26: u(br) Uncertainty in equipment | J26: 1
G27: u(bm) Uncertainty in measurements | J27: =(((MAX(G23:J25)-MIN(G23:J25))/2)*((1/(SQRT(3))))) -> 1.7320508
A38: Staff | B38: Approach Channel & Flume Levels
A39: Location | B39: 1 | C39: 2 | D39: 3 | E39: 4 | F39: 5 | G39: 6 | H39: 7 | I39: 8 | J39: 9
A40: A | B40: 2388 | C40: 2388 | D40: 2390 | E40: 2390 | F40: 2388 | G40: 2389 | H40: 2386 | I40: 2386 | J40: 2390
A41: B | D41: 2390 | E41: 2391 | F41: 2389 | G41: 2390 | H41: 2387 | I41: 2388 | J41: 2385
G42: (Uh0) Uncertainty in gauge zero (mm) | J42: =SQRT((((MIN(D40:I41))-MAX(D40:I41))+(C70))^2) -> 17
A59: Appendix B - Survey & Compliance Data (Tariff)
A61: Primary Device (Dimensions in mm) | G61: Sensor Location
A62: Fabriacation Material | C62: Stainless Steel flume and concrete approach | G62: Sensor Type | I62: dB6
A63: Overall Length (mm) | C63: =SUM(C65+C66+C67) -> 2400 | D63: K-Factor (0.6mm or 1.5mm) | F63: 0.6 | G63: Sensor Serial No | I63: 95573/2008 | L63: target | M63: 1993 | N63: 1994
A64: Throat Width (b) | C64: =AVERAGE(G23:J25) -> 650.91667 | D64: Approach Width (B) | F64: =AVERAGE(C23:F25) -> 1041.1667 | G64: Temp Compensation | I64: Built in | L64: base below | M64: 2636 | P64: =M64-M63 -> 643
A65: Throat Length(L) | C65: 1000 | D65: Approach length | F65: 11000 | G65: Distance Upstream | I65: 2100 | L65: upstream | M65: 2628 | P65: =M66-N63 -> 605
A66: Outlet Length | C66: 900 | D66: Offset | F66: 0 | G66: Sun Shading | I66: Yes | L66: exit | M66: 2599 | P66: =M68-M63 -> 610
A67: Inlet Length | C67: 500 | D67: Numerical Coefficient у | F67: 1 | G67: Target Level | I67: 1756 | L67: mid flume | M67: 2602
A68: Flume Depth | C68: 570 | D68: Numerical Coefficient Ø | F68: 1.5 | G68: Zero level | I68: =AVERAGE(I40:I41)-C70 -> 2365 | L68: flume entry | M68: 2603 | P68: 608
A69: Scum Mark | C69: 450 | D69: Numerical Coefficient ѱ | F69: 0 | G69: Target Reference Height | I69: =SUM((I68-I67)^2)^0.5 -> 609 | L69: flume start | M69: 2613 | P69: 608.344
A70: Hump Height (p) | C70: 22 | D70: Flume Cheek Staggered | F70: 0 | G70: Instrument Reading | I70: =J87 -> 608.0662
A71: Vertical Skew (b) | C71: 0 | D71: Vertical Skew (B) | F71: 0 | G71: Head calibration eror U(h1) | I71: =SUM(I70-I69) -> -0.9338
A72: Estimated inlet radius | C72: 781 | D72: Required inlet radius | F72: =SUM(C100-C101)*2 -> 780.5
A74: Instrument Flow / Head Listing | G74: mA Output Checks | L74: Site flow meter curve or check points
A75: Point No | B75: Level mm | C75: Flow L/sec | D75: Point No | E75: Level mm | F75: Flow L/sec | G75: Site Meter | H75: Dvm Output | I75: Calc Output | J75: % Diff | L75: Stage | M75: head (H) | N75: Flow (Q)
A76: 1 | B76: =M76 -> 157.8 | C76: =N76 -> 71.93 | D76: 12 | E76: =M87 -> 0 | F76: =N87 -> 0 | G76: 112.4 | H76: 7.99 | I76: =(G76/$C$96)*16+4 -> 7.9848441 | J76: =(I76-H76)/H76*100 -> -0.064529156 | L76: 1 | M76: 157.8 | N76: 71.93
A77: 2 | B77: =M77 -> 315.6 | C77: =N77 -> 207.8 | D77: 13 | E77: =M88 -> 0 | F77: =N88 -> 0 | G77: 338.2 | H77: 15.998 | I77: =(G77/$C$96)*16+4 -> 15.989985 | J77: =(I77-H77)/H77*100 -> -0.050101818 | L77: 2 | M77: 315.6 | N77: 207.8
A78: 3 | B78: =M78 -> 0 | C78: =N78 -> 0 | D78: 14 | E78: =M89 -> 0 | F78: =N89 -> 0 | G78: 451.1 | H78: 19.997 | I78: =(G78/$C$96)*16+4 -> 19.992555 | J78: =(I78-H78)/H78*100 -> -0.022228302 | L78: 3
A79: 4 | B79: =M79 -> 0 | C79: =N79 -> 0 | D79: 15 | E79: =M90 -> 0 | F79: =N90 -> 0 | G79: Mean Error % | J79: =AVERAGE(J76:J78) -> -0.045619758 | L79: 4
...

Sheet Data & Results
B1: Appendix C - Stage discharge Relationship and Flow Uncertainty (Tariff)
B4: Primary Device Critical Dimensions | F4: Stage | G4: Head | O4: Flow Rate | P4: Uncertainty
B5: Throat breadth in metres | C5: b | D5: ='Input Data'!C101/1000 -> 0.65091667 | E5: M | F5: 0 | G5: (mm) | H5: CD | I5: Cv | J5: δ*/L | K5: Re/105 | L5: Uc | M5: Uh | N5: Ub | O5: (Q) l/s | P5: U(Q) (±%)
B6: Length of throat in metres | C6: L | D6: ='Input Data'!C102/1000 -> 1 | E6: M | F6: =IF(F5>=Num,"",F5+1) -> 1 | G6: =hi -> 0 | H6: 0 | I6: 0 | J6: 0 | K6: 0 | L6: 0 | M6: 0 | N6: 0 | O6: 0 | P6: 100 | Q6: 8
B7: Approach breadth in metres | C7: B | D7: ='Input Data'!C100/1000 -> 1.0411667 | E7: M | F7: =IF(F6>=Num,"",F6+1) -> 2 | G7: =IF(AND(F6<>"",G6<2000),G6+step,"") -> 27.684211 | H7: =SUM((((1-(0.006*(L/b)))*((1-((0.003*(L/(G7/1000)))))^(1.5))))) -> 0.83417824 | I7: =IF(G7<>"",VLOOKUP(G7,Calculations!$AV$2:$BA$2001,4),"") -> 1.0218719 | J7: =IF(G7<>"",VLOOKUP(G7,Calculations!$AV$2:$BA$2001,5),"") -> 0.0027333333 | K7: =IF(G7<>"",VLOOKUP(G7,Calculations!$AV$2:$BA$2001,6),"") -> 3.5068687 | L7: =SUM((0.5+10*(I7-H7))) -> 2.3769361 | M7: =(100*((SQRT(($D$22^2)+($D$23^2)+((($D$24))^2)))/G7)) -> 13.069399 | N7: =$D$21 -> 0.26976453 | O7: =SUM(((2/3)^(3/2))*(gn^0.5)*(H7)*(I7)*(b)*((G7/1000)^(3/2)))*1000 -> 4.3573908 | P7: =(SQRT((L7^2)+((1.5^2)*(M7^2))+(N7^2)+($D$25^2)+($D$26^2)+($D$27^2)+($D$28^2))*2+IF(G7/1000>=$D$6/2,2,0)) -> 39.751392 | Q7: 8
B8: Height of hump in metres | C8: p | D8: ='Input Data'!C103/1000 -> 0.022 | E8: M | F8: =IF(F7>=Num,"",F7+1) -> 3 | G8: =IF(AND(F7<>"",G7<2000),G7+step,"") -> 55.368421 | H8: =SUM((((1-(0.006*(L/b)))*((1-((0.003*(L/(G8/1000)))))^(1.5))))) -> 0.91135844 | I8: =IF(G8<>"",VLOOKUP(G8,Calculations!$AV$2:$BA$2001,4),"") -> 1.0423046 | J8: =IF(G8<>"",VLOOKUP(G8,Calculations!$AV$2:$BA$2001,5),"") -> 0.0029666667 | K8: =IF(G8<>"",VLOOKUP(G8,Calculations!$AV$2:$BA$2001,6),"") -> 5.1679301 | L8: =SUM((0.5+10*(I8-H8))) -> 1.8094613 | M8: =(100*((SQRT(($D$22^2)+($D$23^2)+((($D$24))^2)))/G8)) -> 6.5346996 | N8: =$D$21 -> 0.26976453 | O8: =SUM(((2/3)^(3/2))*(gn^0.5)*(H8)*(I8)*(b)*((G8/1000)^(3/2)))*1000 -> 13.734096 | P8: =(SQRT((L8^2)+((1.5^2)*(M8^2))+(N8^2)+($D$25^2)+($D$26^2)+($D$27^2)+($D$28^2))*2+IF(G8/1000>=$D$6/2,2,0)) -> 20.437915 | Q8: 8
B9: Roughness value | C9: ks | D9: ='Input Data'!F63/1000 -> 0.0006 | E9: M | F9: =IF(F8>=Num,"",F8+1) -> 4 | G9: =IF(AND(F8<>"",G8<2000),G8+step,"") -> 83.052632 | H9: =SUM((((1-(0.006*(L/b)))*((1-((0.003*(L/(G9/1000)))))^(1.5))))) -> 0.9375869 | I9: =IF(G9<>"",VLOOKUP(G9,Calculations!$AV$2:$BA$2001,4),"") -> 1.053262 | J9: =IF(G9<>"",VLOOKUP(G9,Calculations!$AV$2:$BA$2001,5),"") -> 0.0039666667 | K9: =IF(G9<>"",VLOOKUP(G9,Calculations!$AV$2:$BA$2001,6),"") -> 6.3847705 | L9: =SUM((0.5+10*(I9-H9))) -> 1.6567511 | M9: =(100*((SQRT(($D$22^2)+($D$23^2)+((($D$24))^2)))/G9)) -> 4.3564664 | N9: =$D$21 -> 0.26976453 | O9: =SUM(((2/3)^(3/2))*(gn^0.5)*(H9)*(I9)*(b)*((G9/1000)^(3/2)))*1000 -> 26.230167 | P9: =(SQRT((L9^2)+((1.5^2)*(M9^2))+(N9^2)+($D$25^2)+($D$26^2)+($D$27^2)+($D$28^2))*2+IF(G9/1000>=$D$6/2,2,0)) -> 14.21547 | Q9: 8
B10: Viscosity | C10: nu | D10: 1.141e-06 | E10: m2/s | F10: =IF(F9>=Num,"",F9+1) -> 5 | G10: =IF(AND(F9<>"",G9<2000),G9+step,"") -> 110.73684 | H10: =SUM((((1-(0.006*(L/b)))*((1-((0.003*(L/(G10/1000)))))^(1.5))))) -> 0.95079386 | I10: =IF(G10<>"",VLOOKUP(G10,Calculations!$AV$2:$BA$2001,4),"") -> 1.061394 | J10: =IF(G10<>"",VLOOKUP(G10,Calculations!$AV$2:$BA$2001,5),"") -> 0.0041 | K10: =IF(G10<>"",VLOOKUP(G10,Calculations!$AV$2:$BA$2001,6),"") -> 7.4086908 | L10: =SUM((0.5+10*(I10-H10))) -> 1.6060011 | M10: =(100*((SQRT(($D$22^2)+($D$23^2)+((($D$24))^2)))/G10)) -> 3.2673498 | N10: =$D$21 -> 0.26976453 | O10: =SUM(((2/3)^(3/2))*(gn^0.5)*(H10)*(I10)*(b)*((G10/1000)^(3/2)))*1000 -> 41.269024 | P10: =(SQRT((L10^2)+((1.5^2)*(M10^2))+(N10^2)+($D$25^2)+($D$26^2)+($D$27^2)+($D$28^2))*2+IF(G10/1000>=$D$6/2,2,0)) -> 11.255586 | Q10: 8
B11: Gravity constant | C11: gn | D11: 9.81 | E11: m/s2 | F11: =IF(F10>=Num,"",F10+1) -> 6 | G11: =IF(AND(F10<>"",G10<2000),G10+step,"") -> 138.42105 | H11: =SUM((((1-(0.006*(L/b)))*((1-((0.003*(L/(G11/1000)))))^(1.5))))) -> 0.95874755 | I11: =IF(G11<>"",VLOOKUP(G11,Calculations!$AV$2:$BA$2001,4),"") -> 1.067257 | J11: =IF(G11<>"",VLOOKUP(G11,Calculations!$AV$2:$BA$2001,5),"") -> 0.0043 | K11: =IF(G11<>"",VLOOKUP(G11,Calculations!$AV$2:$BA$2001,6),"") -> 8.3380891 | L11: =SUM((0.5+10*(I11-H11))) -> 1.5850943 | M11: =(100*((SQRT(($D$22^2)+($D$23^2)+((($D$24))^2)))/G11)) -> 2.6138798 | N11: =$D$21 -> 0.26976453 | O11: =SUM(((2/3)^(3/2))*(gn^0.5)*(H11)*(I11)*(b)*((G11/1000)^(3/2)))*1000 -> 58.47894 | P11: =(SQRT((L11^2)+((1.5^2)*(M11^2))+(N11^2)+($D$25^2)+($D$26^2)+($D$27^2)+($D$28^2))*2+IF(G11/1000>=$D$6/2,2,0)) -> 9.5829274 | Q11: 8
F12: =IF(F11>=Num,"",F11+1) -> 7 | G12: =IF(AND(F11<>"",G11<2000),G11+step,"") -> 166.10526 | H12: =SUM((((1-(0.006*(L/b)))*((1-((0.003*(L/(G12/1000)))))^(1.5))))) -> 0.96406226 | I12: =IF(G12<>"",VLOOKUP(G12,Calculations!$AV$2:$BA$2001,4),"") -> 1.07141 | J12: =IF(G12<>"",VLOOKUP(G12,Calculations!$AV$2:$BA$2001,5),"") -> 0.0046 | K12: =IF(G12<>"",VLOOKUP(G12,Calculations!$AV$2:$BA$2001,6),"") -> 9.1702153 | L12: =SUM((0.5+10*(I12-H12))) -> 1.5734773 | M12: =(100*((SQRT(($D$22^2)+($D$23^2)+((($D$24))^2)))/G12)) -> 2.1782332 | N12: =$D$21 -> 0.26976453 | O12: =SUM(((2/3)^(3/2))*(gn^0.5)*(H12)*(I12)*(b)*((G12/1000)^(3/2)))*1000 -> 77.59949 | P12: =(SQRT((L12^2)+((1.5^2)*(M12^2))+(N12^2)+($D$25^2)+($D$26^2)+($D$27^2)+($D$28^2))*2+IF(G12/1000>=$D$6/2,2,0)) -> 8.5379572 | Q12: 8
B13: Table format | F13: =IF(F12>=Num,"",F12+1) -> 8 | G13: =IF(AND(F12<>"",G12<2000),G12+step,"") -> 193.78947 | H13: =SUM((((1-(0.006*(L/b)))*((1-((0.003*(L/(G13/1000)))))^(1.5))))) -> 0.96786447 | I13: =IF(G13<>"",VLOOKUP(G13,Calculations!$AV$2:$BA$2001,4),"") -> 1.0748775 | J13: =IF(G13<>"",VLOOKUP(G13,Calculations!$AV$2:$BA$2001,5),"") -> 0.0046 | K13: =IF(G13<>"",VLOOKUP(G13,Calculations!$AV$2:$BA$2001,6),"") -> 9.9182713 | L13: =SUM((0.5+10*(I13-H13))) -> 1.5701307 | M13: =(100*((SQRT(($D$22^2)+($D$23^2)+((($D$24))^2)))/G13)) -> 1.867057 | N13: =$D$21 -> 0.26976453 | O13: =SUM(((2/3)^(3/2))*(gn^0.5)*(H13)*(I13)*(b)*((G13/1000)^(3/2)))*1000 -> 98.489928 | P13: =(SQRT((L13^2)+((1.5^2)*(M13^2))+(N13^2)+($D$25^2)+($D$26^2)+($D$27^2)+($D$28^2))*2+IF(G13/1000>=$D$6/2,2,0)) -> 7.8438161 | Q13: 8
B14: Initial gauged height | D14: 0 | E14: mm | F14: =IF(F13>=Num,"",F13+1) -> 9 | G14: =IF(AND(F13<>"",G13<2000),G13+step,"") -> 221.47368 | H14: =SUM((((1-(0.006*(L/b)))*((1-((0.003*(L/(G14/1000)))))^(1.5))))) -> 0.97071941 | I14: =IF(G14<>"",VLOOKUP(G14,Calculations!$AV$2:$BA$2001,4),"") -> 1.0775586 | J14: =IF(G14<>"",VLOOKUP(G14,Calculations!$AV$2:$BA$2001,5),"") -> 0.0047333333 | K14: =IF(G14<>"",VLOOKUP(G14,Calculations!$AV$2:$BA$2001,6),"") -> 10.633857 | L14: =SUM((0.5+10*(I14-H14))) -> 1.5683923 | M14: =(100*((SQRT(($D$22^2)+($D$23^2)+((($D$24))^2)))/G14)) -> 1.6336749 | N14: =$D$21 -> 0.26976453 | O14: =SUM(((2/3)^(3/2))*(gn^0.5)*(H14)*(I14)*(b)*((G14/1000)^(3/2)))*1000 -> 120.98759 | P14: =(SQRT((L14^2)+((1.5^2)*(M14^2))+(N14^2)+($D$25^2)+($D$26^2)+($D$27^2)+($D$28^2))*2+IF(G14/1000>=$D$6/2,2,0)) -> 7.3587059 | Q14: 8
B15: Step size between stages | D15: =P27/19 -> 27.684211 | E15: mm | F15: =IF(F14>=Num,"",F14+1) -> 10 | G15: =IF(AND(F14<>"",G14<2000),G14+step,"") -> 249.15789 | H15: =SUM((((1-(0.006*(L/b)))*((1-((0.003*(L/(G15/1000)))))^(1.5))))) -> 0.97294185 | I15: =IF(G15<>"",VLOOKUP(G15,Calculations!$AV$2:$BA$2001,4),"") -> 1.0798971 | J15: =IF(G15<>"",VLOOKUP(G15,Calculations!$AV$2:$BA$2001,5),"") -> 0.0047333333 | K15: =IF(G15<>"",VLOOKUP(G15,Calculations!$AV$2:$BA$2001,6),"") -> 11.309462 | L15: =SUM((0.5+10*(I15-H15))) -> 1.5695523 | M15: =(100*((SQRT(($D$22^2)+($D$23^2)+((($D$24))^2)))/G15)) -> 1.4521555 | N15: =$D$21 -> 0.26976453 | O15: =SUM(((2/3)^(3/2))*(gn^0.5)*(H15)*(I15)*(b)*((G15/1000)^(3/2)))*1000 -> 145.0121 | P15: =(SQRT((L15^2)+((1.5^2)*(M15^2))+(N15^2)+($D$25^2)+($D$26^2)+($D$27^2)+($D$28^2))*2+IF(G15/1000>=$D$6/2,2,0)) -> 7.0088422 | Q15: 8
B16: Number of stages | D16: 20 | F16: =IF(F15>=Num,"",F15+1) -> 11 | G16: =IF(AND(F15<>"",G15<2000),G15+step,"") -> 276.84211 | H16: =SUM((((1-(0.006*(L/b)))*((1-((0.003*(L/(G16/1000)))))^(1.5))))) -> 0.97472102 | I16: =IF(G16<>"",VLOOKUP(G16,Calculations!$AV$2:$BA$2001,4),"") -> 1.0817718 | J16: =IF(G16<>"",VLOOKUP(G16,Calculations!$AV$2:$BA$2001,5),"") -> 0.0047333333 | K16: =IF(G16<>"",VLOOKUP(G16,Calculations!$AV$2:$BA$2001,6),"") -> 11.925021 | L16: =SUM((0.5+10*(I16-H16))) -> 1.5705078 | M16: =(100*((SQRT(($D$22^2)+($D$23^2)+((($D$24))^2)))/G16)) -> 1.3069399 | N16: =$D$21 -> 0.26976453 | O16: =SUM(((2/3)^(3/2))*(gn^0.5)*(H16)*(I16)*(b)*((G16/1000)^(3/2)))*1000 -> 170.44616 | P16: =(SQRT((L16^2)+((1.5^2)*(M16^2))+(N16^2)+($D$25^2)+($D$26^2)+($D$27^2)+($D$28^2))*2+IF(G16/1000>=$D$6/2,2,0)) -> 6.7475847 | Q16: 8
F17: =IF(F16>=Num,"",F16+1) -> 12 | G17: =IF(AND(F16<>"",G16<2000),G16+step,"") -> 304.52632 | H17: =SUM((((1-(0.006*(L/b)))*((1-((0.003*(L/(G17/1000)))))^(1.5))))) -> 0.97617751 | I17: =IF(G17<>"",VLOOKUP(G17,Calculations!$AV$2:$BA$2001,4),"") -> 1.0832867 | J17: =IF(G17<>"",VLOOKUP(G17,Calculations!$AV$2:$BA$2001,5),"") -> 0.0048333333 | K17: =IF(G17<>"",VLOOKUP(G17,Calculations!$AV$2:$BA$2001,6),"") -> 12.527804 | L17: =SUM((0.5+10*(I17-H17))) -> 1.5710914 | M17: =(100*((SQRT(($D$22^2)+($D$23^2)+((($D$24))^2)))/G17)) -> 1.1881272 | N17: =$D$21 -> 0.26976453 | O17: =SUM(((2/3)^(3/2))*(gn^0.5)*(H17)*(I17)*(b)*((G17/1000)^(3/2)))*1000 -> 197.21159 | P17: =(SQRT((L17^2)+((1.5^2)*(M17^2))+(N17^2)+($D$25^2)+($D$26^2)+($D$27^2)+($D$28^2))*2+IF(G17/1000>=$D$6/2,2,0)) -> 6.5474591 | Q17: 8
B18: Uncertainties | F18: =IF(F17>=Num,"",F17+1) -> 13 | G18: =IF(AND(F17<>"",G17<2000),G17+step,"") -> 332.21053 | H18: =SUM((((1-(0.006*(L/b)))*((1-((0.003*(L/(G18/1000)))))^(1.5))))) -> 0.97739181 | I18: =IF(G18<>"",VLOOKUP(G18,Calculations!$AV$2:$BA$2001,4),"") -> 1.0846911 | J18: =IF(G18<>"",VLOOKUP(G18,Calculations!$AV$2:$BA$2001,5),"") -> 0.0048333333 | K18: =IF(G18<>"",VLOOKUP(G18,Calculations!$AV$2:$BA$2001,6),"") -> 13.106612 | L18: =SUM((0.5+10*(I18-H18))) -> 1.5729928 | M18: =(100*((SQRT(($D$22^2)+($D$23^2)+((($D$24))^2)))/G18)) -> 1.0891166 | N18: =$D$21 -> 0.26976453 | O18: =SUM(((2/3)^(3/2))*(gn^0.5)*(H18)*(I18)*(b)*((G18/1000)^(3/2)))*1000 -> 225.27752 | P18: =(SQRT((L18^2)+((1.5^2)*(M18^2))+(N18^2)+($D$25^2)+($D$26^2)+($D$27^2)+($D$28^2))*2+IF(G18/1000>=$D$6/2,2,0)) -> 6.3924871 | Q18: 8
B19: Uncertainty in equipment | C19: u(br) | D19: =(('Input Data'!J26/2)*((1/((SQRT(3)))))) -> 0.28867513 | E19: mm | F19: =IF(F18>=Num,"",F18+1) -> 14 | G19: =IF(AND(F18<>"",G18<2000),G18+step,"") -> 359.89474 | H19: =SUM((((1-(0.006*(L/b)))*((1-((0.003*(L/(G19/1000)))))^(1.5))))) -> 0.97841968 | I19: =IF(G19<>"",VLOOKUP(G19,Calculations!$AV$2:$BA$2001,4),"") -> 1.0858631 | J19: =IF(G19<>"",VLOOKUP(G19,Calculations!$AV$2:$BA$2001,5),"") -> 0.0048333333 | K19: =IF(G19<>"",VLOOKUP(G19,Calculations!$AV$2:$BA$2001,6),"") -> 13.641625 | L19: =SUM((0.5+10*(I19-H19))) -> 1.5744344 | M19: =(100*((SQRT(($D$22^2)+($D$23^2)+((($D$24))^2)))/G19)) -> 1.0053384 | N19: =$D$21 -> 0.26976453 | O19: =SUM(((2/3)^(3/2))*(gn^0.5)*(H19)*(I19)*(b)*((G19/1000)^(3/2)))*1000 -> 254.55786 | P19: =(SQRT((L19^2)+((1.5^2)*(M19^2))+(N19^2)+($D$25^2)+($D$26^2)+($D$27^2)+($D$28^2))*2+IF(G19/1000>=$D$6/2,2,0)) -> 6.2691957 | Q19: 8
B20: Uncertainty in measurements | C20: u(bm) | D20: ='Input Data'!J27 -> 1.7320508 | E20: mm | F20: =IF(F19>=Num,"",F19+1) -> 15 | G20: =IF(AND(F19<>"",G19<2000),G19+step,"") -> 387.57895 | H20: =SUM((((1-(0.006*(L/b)))*((1-((0.003*(L/(G20/1000)))))^(1.5))))) -> 0.979301 | I20: =IF(G20<>"",VLOOKUP(G20,Calculations!$AV$2:$BA$2001,4),"") -> 1.0867674 | J20: =IF(G20<>"",VLOOKUP(G20,Calculations!$AV$2:$BA$2001,5),"") -> 0.0049666667 | K20: =IF(G20<>"",VLOOKUP(G20,Calculations!$AV$2:$BA$2001,6),"") -> 14.170109 | L20: =SUM((0.5+10*(I20-H20))) -> 1.5746641 | M20: =(100*((SQRT(($D$22^2)+($D$23^2)+((($D$24))^2)))/G20)) -> 0.93352851 | N20: =$D$21 -> 0.26976453 | O20: =SUM(((2/3)^(3/2))*(gn^0.5)*(H20)*(I20)*(b)*((G20/1000)^(3/2)))*1000 -> 284.98112 | P20: =(SQRT((L20^2)+((1.5^2)*(M20^2))+(N20^2)+($D$25^2)+($D$26^2)+($D$27^2)+($D$28^2))*2+IF(G20/1000>=$D$6/2,2,0)) -> 6.1686821 | Q20: 8
B21: Combined uncertainty in throat width | C21: u(b) | D21: =SUM(SQRT((D19^2)+(D20^2)))/((b*1000))*100 -> 0.26976453 | E21: % | F21: =IF(F20>=Num,"",F20+1) -> 16 | G21: =IF(AND(F20<>"",G20<2000),G20+step,"") -> 415.26316 | H21: =SUM((((1-(0.006*(L/b)))*((1-((0.003*(L/(G21/1000)))))^(1.5))))) -> 0.98006503 | I21: =IF(G21<>"",VLOOKUP(G21,Calculations!$AV$2:$BA$2001,4),"") -> 1.0877046 | J21: =IF(G21<>"",VLOOKUP(G21,Calculations!$AV$2:$BA$2001,5),"") -> 0.0049666667 | K21: =IF(G21<>"",VLOOKUP(G21,Calculations!$AV$2:$BA$2001,6),"") -> 14.684424 | L21: =SUM((0.5+10*(I21-H21))) -> 1.5763962 | M21: =(100*((SQRT(($D$22^2)+($D$23^2)+((($D$24))^2)))/G21)) -> 0.87129328 | N21: =$D$21 -> 0.26976453 | O21: =SUM(((2/3)^(3/2))*(gn^0.5)*(H21)*(I21)*(b)*((G21/1000)^(3/2)))*1000 -> 316.57309 | P21: =(SQRT((L21^2)+((1.5^2)*(M21^2))+(N21^2)+($D$25^2)+($D$26^2)+($D$27^2)+($D$28^2))*2+IF(G21/1000>=$D$6/2,2,0)) -> 6.0879848 | Q21: 8
B22: Relative datum uncertainty | C22: u(E) | D22: =SUM((1/(SQRT(6)))*('Input Data'!J42/2)) -> 3.4701105 | E22: mm | F22: =IF(F21>=Num,"",F21+1) -> 17 | G22: =IF(AND(F21<>"",G21<2000),G21+step,"") -> 442.94737 | H22: =SUM((((1-(0.006*(L/b)))*((1-((0.003*(L/(G22/1000)))))^(1.5))))) -> 0.98073372 | I22: =IF(G22<>"",VLOOKUP(G22,Calculations!$AV$2:$BA$2001,4),"") -> 1.0885073 | J22: =IF(G22<>"",VLOOKUP(G22,Calculations!$AV$2:$BA$2001,5),"") -> 0.0049666667 | K22: =IF(G22<>"",VLOOKUP(G22,Calculations!$AV$2:$BA$2001,6),"") -> 15.163917 | L22: =SUM((0.5+10*(I22-H22))) -> 1.5777356 | M22: =(100*((SQRT(($D$22^2)+($D$23^2)+((($D$24))^2)))/G22)) -> 0.81683745 | N22: =$D$21 -> 0.26976453 | O22: =SUM(((2/3)^(3/2))*(gn^0.5)*(H22)*(I22)*(b)*((G22/1000)^(3/2)))*1000 -> 349.24777 | P22: =(SQRT((L22^2)+((1.5^2)*(M22^2))+(N22^2)+($D$25^2)+($D$26^2)+($D$27^2)+($D$28^2))*2+IF(G22/1000>=$D$6/2,2,0)) -> 6.0210548 | Q22: 8
B23: Uncertainty in flowmeter calibration | C23: u(h1) | D23: ='Input Data'!I71 -> -0.9338 | E23: mm | F23: =IF(F22>=Num,"",F22+1) -> 18 | G23: =IF(AND(F22<>"",G22<2000),G22+step,"") -> 470.63158 | H23: =SUM((((1-(0.006*(L/b)))*((1-((0.003*(L/(G23/1000)))))^(1.5))))) -> 0.98132386 | I23: =IF(G23<>"",VLOOKUP(G23,Calculations!$AV$2:$BA$2001,4),"") -> 1.0892515 | J23: =IF(G23<>"",VLOOKUP(G23,Calculations!$AV$2:$BA$2001,5),"") -> 0.0049666667 | K23: =IF(G23<>"",VLOOKUP(G23,Calculations!$AV$2:$BA$2001,6),"") -> 15.645704 | L23: =SUM((0.5+10*(I23-H23))) -> 1.5792764 | M23: =(100*((SQRT(($D$22^2)+($D$23^2)+((($D$24))^2)))/G23)) -> 0.76878818 | N23: =$D$21 -> 0.26976453 | O23: =SUM(((2/3)^(3/2))*(gn^0.5)*(H23)*(I23)*(b)*((G23/1000)^(3/2)))*1000 -> 382.98797 | P23: =(SQRT((L23^2)+((1.5^2)*(M23^2))+(N23^2)+($D$25^2)+($D$26^2)+($D$27^2)+($D$28^2))*2+IF(G23/1000>=$D$6/2,2,0)) -> 5.9654727 | Q23: 8
B24: Uncertainty in flowmeter repeatability (68%cl) | C24: u(h2) | D24: ='Input Data'!J86 -> 0.42122735 | E24: mm | F24: =IF(F23>=Num,"",F23+1) -> 19 | G24: =IF(AND(F23<>"",G23<2000),G23+step,"") -> 498.31579 | H24: =SUM((((1-(0.006*(L/b)))*((1-((0.003*(L/(G24/1000)))))^(1.5))))) -> 0.98184853 | I24: =IF(G24<>"",VLOOKUP(G24,Calculations!$AV$2:$BA$2001,4),"") -> 1.0898088 | J24: =IF(G24<>"",VLOOKUP(G24,Calculations!$AV$2:$BA$2001,5),"") -> 0.0050666667 | K24: =IF(G24<>"",VLOOKUP(G24,Calculations!$AV$2:$BA$2001,6),"") -> 16.109277 | L24: =SUM((0.5+10*(I24-H24))) -> 1.579603 | M24: =(100*((SQRT(($D$22^2)+($D$23^2)+((($D$24))^2)))/G24)) -> 0.72607773 | N24: =$D$21 -> 0.26976453 | O24: =SUM(((2/3)^(3/2))*(gn^0.5)*(H24)*(I24)*(b)*((G24/1000)^(3/2)))*1000 -> 417.70993 | P24: =(SQRT((L24^2)+((1.5^2)*(M24^2))+(N24^2)+($D$25^2)+($D$26^2)+($D$27^2)+($D$28^2))*2+IF(G24/1000>=$D$6/2,2,0)) -> 5.9174635 | Q24: 8
B25: Telemetry Uncertainty | C25: u(t) | D25: ='Input Data'!H8 -> 2 | E25: % | F25: =IF(F24>=Num,"",F24+1) -> 20 | G25: =P27 -> 526 | H25: =SUM((((1-(0.006*(L/b)))*((1-((0.003*(L/(G25/1000)))))^(1.5))))) -> 0.98231805 | I25: =IF(G25<>"",VLOOKUP(G25,Calculations!$AV$2:$BA$2001,4),"") -> 1.0904134 | J25: =IF(G25<>"",VLOOKUP(G25,Calculations!$AV$2:$BA$2001,5),"") -> 0.0050666667 | K25: =IF(G25<>"",VLOOKUP(G25,Calculations!$AV$2:$BA$2001,6),"") -> 16.563545 | L25: =SUM((0.5+10*(I25-H25))) -> 1.5809532 | M25: =(100*((SQRT(($D$22^2)+($D$23^2)+((($D$24))^2)))/G25)) -> 0.68786311 | N25: =$D$21 -> 0.26976453 | O25: =SUM(((2/3)^(3/2))*(gn^0.5)*(H25)*(I25)*(b)*((G25/1000)^(3/2)))*1000 -> 453.4662 | P25: =(SQRT((L25^2)+((1.5^2)*(M25^2))+(N25^2)+($D$25^2)+($D$26^2)+($D$27^2)+($D$28^2))*2+IF(G25/1000>=$D$6/2,2,0)) -> 7.8776819 | Q25: 8
B26: Look Up Table Uncertainty | C26: U(lu) | D26: ='Input Data'!H9 -> 1 | E26: % | F26: =IF(F25>=Num,"",F25+1) | G26: Instrument
B27: Custom Uncertainty 1 | C27: U(a1) | D27: 0 | E27: % | F27: =IF(F26>=Num,"",F26+1) | G27: Instrument H max (mm) | P27: ='Input Data'!C95 -> 526
B28: Custom Uncertainty 2 | C28: U(a2) | D28: 0 | E28: % | F28: =IF(F27>=Num,"",F27+1) | G28: Instrument Q Max (l/s) | P28: ='Input Data'!C96 -> 451.31
F29: =IF(F28>=Num,"",F28+1)
B30: Daily Weighted uncertainty results | D30: Date used | E30: Volume (Q) m3/day | O30: Uncertainty UQ (±%)
B31: Calculated DWF (24hr diurnal) | D31: n/a | E31: ='Input Data'!C10 -> 14778 | O31: ± | P31: ='DWF Uncertainty'!F104/100 -> 0.06833744
B32: Calculated FFT (24hr diurnal) | D32: n/a | E32: ='Input Data'!C9 -> 31577 | O32: ± | P32: ='FFT Uncertainty'!F104/100 -> 0.064289903
B33: Real data DWF (24hr) | D33: ='Uncertainty sheet'!F2 -> 45805 | E33: ='Uncertainty sheet'!D104 -> 13734.293 | O33: ± | P33: ='Uncertainty sheet'!F104/100 -> 0.070008952
F34: =IF(E33>=Num,"",E33+1)
F35: =IF(F34>=Num,"",F34+1)
B41: * Average installed dimensions used to correctly calculate flow / head curve
B42: ** Quantified Errors & uncertainties following installation of flume by Civil Contrators
H45: =IF(G45<>"",VLOOKUP(G45,Calculations!$AV$2:$BA$2001,3),"") | I45: =IF(G45<>"",VLOOKUP(G45,Calculations!$AV$2:$BA$2001,4),"") | J45: =IF(G45<>"",VLOOKUP(G45,Calculations!$AV$2:$BA$2001,5),"") | K45: =IF(G45<>"",VLOOKUP(G45,Calculations!$AV$2:$BA$2001,6),"") | L45: =SUM((I45-H45)*20)+1 -> #VALUE! | M45: =(100*((SQRT(($D$22^2)+($D$23^2)+((2*($D$24))^2)))/G45)) -> #DIV/0! | N45: =$D$21 -> 0.26976453 | P45: =SQRT((L45^2)+((1.5^2)*(M45^2))+(N45^2)+($D$25^2)+($D$26^2)+($D$27^2)+($D$28^2)) -> #VALUE!
H46: =IF(G46<>"",VLOOKUP(G46,Calculations!$AV$2:$BA$2001,3),"") | I46: =IF(G46<>"",VLOOKUP(G46,Calculations!$AV$2:$BA$2001,4),"") | J46: =IF(G46<>"",VLOOKUP(G46,Calculations!$AV$2:$BA$2001,5),"") | K46: =IF(G46<>"",VLOOKUP(G46,Calculations!$AV$2:$BA$2001,6),"") | L46: =SUM((I46-H46)*20)+1 -> #VALUE! | M46: =(100*((SQRT(($D$22^2)+($D$23^2)+((2*($D$24))^2)))/G46)) -> #DIV/0! | N46: =$D$21 -> 0.26976453 | P46: =SQRT((L46^2)+((1.5^2)*(M46^2))+(N46^2)+($D$25^2)+($D$26^2)+($D$27^2)+($D$28^2)) -> #VALUE!
H47: =IF(G47<>"",VLOOKUP(G47,Calculations!$AV$2:$BA$2001,3),"") | I47: =IF(G47<>"",VLOOKUP(G47,Calculations!$AV$2:$BA$2001,4),"") | J47: =IF(G47<>"",VLOOKUP(G47,Calculations!$AV$2:$BA$2001,5),"") | K47: =IF(G47<>"",VLOOKUP(G47,Calculations!$AV$2:$BA$2001,6),"") | L47: =SUM((I47-H47)*20)+1 -> #VALUE! | M47: =(100*((SQRT(($D$22^2)+($D$23^2)+((2*($D$24))^2)))/G47)) -> #DIV/0! | N47: =$D$21 -> 0.26976453 | P47: =SQRT((L47^2)+((1.5^2)*(M47^2))+(N47^2)+($D$25^2)+($D$26^2)+($D$27^2)+($D$28^2)) -> #VALUE!
H48: =IF(G48<>"",VLOOKUP(G48,Calculations!$AV$2:$BA$2001,3),"") | I48: =IF(G48<>"",VLOOKUP(G48,Calculations!$AV$2:$BA$2001,4),"") | J48: =IF(G48<>"",VLOOKUP(G48,Calculations!$AV$2:$BA$2001,5),"") | K48: =IF(G48<>"",VLOOKUP(G48,Calculations!$AV$2:$BA$2001,6),"") | L48: =SUM((I48-H48)*20)+1 -> #VALUE! | M48: =(100*((SQRT(($D$22^2)+($D$23^2)+((2*($D$24))^2)))/G48)) -> #DIV/0! | N48: =$D$21 -> 0.26976453 | P48: =SQRT((L48^2)+((1.5^2)*(M48^2))+(N48^2)+($D$25^2)+($D$26^2)+($D$27^2)+($D$28^2)) -> #VALUE!
H49: =IF(G49<>"",VLOOKUP(G49,Calculations!$AV$2:$BA$2001,3),"") | I49: =IF(G49<>"",VLOOKUP(G49,Calculations!$AV$2:$BA$2001,4),"") | J49: =IF(G49<>"",VLOOKUP(G49,Calculations!$AV$2:$BA$2001,5),"") | K49: =IF(G49<>"",VLOOKUP(G49,Calculations!$AV$2:$BA$2001,6),"") | L49: =SUM((I49-H49)*20)+1 -> #VALUE! | M49: =(100*((SQRT(($D$22^2)+($D$23^2)+((2*($D$24))^2)))/G49)) -> #DIV/0! | N49: =$D$21 -> 0.26976453 | P49: =SQRT((L49^2)+((1.5^2)*(M49^2))+(N49^2)+($D$25^2)+($D$26^2)+($D$27^2)+($D$28^2)) -> #VALUE!
...

Sheet Uncertainty sheet
A1: Appendix D - Calculated Daily Weighted Uncertainty (Tariff)
A2: Daily Discharge Consent Volume m3/day | D2: ='Input Data'!C6 -> 31577 | E2: Flow Data: | F2: 45805
A3: Time | B3: Average | C3: 15min | D3: Total | E3: Uncertainty | F3: Contributions
B4: Flow | C4: Volume | D4: Volume | F4: to the
F5: Uncertainty in
B6: (l/s) | C6: (m3) | D6: (m3) | E6: (±%) | F6: TDV (±%)
A7: 0 | B7: 141.0427 | C7: =SUM(B7*0.9) -> 126.93843 | D7: =SUM(C7) -> 126.93843 | E7: =VLOOKUP(B7,'Data & Results'!$O$6:$P$25,2,TRUE) -> 7.3587059 | F7: =SUM(C7*E7)/$D$104 -> 0.068012421
A8: 0.010416667 | B8: 142.85556 | C8: =SUM(B8*0.9) -> 128.57 | D8: =SUM(D7+C8) -> 255.50843 | E8: =VLOOKUP(B8,'Data & Results'!$O$6:$P$25,2,TRUE) -> 7.3587059 | F8: =SUM(C8*E8)/$D$104 -> 0.068886603
A9: 0.020833333 | B9: 146.70778 | C9: =SUM(B9*0.9) -> 132.037 | D9: =SUM(D8+C9) -> 387.54543 | E9: =VLOOKUP(B9,'Data & Results'!$O$6:$P$25,2,TRUE) -> 7.0088422 | F9: =SUM(C9*E9)/$D$104 -> 0.067380714
A10: 0.03125 | B10: 126.42333 | C10: =SUM(B10*0.9) -> 113.781 | D10: =SUM(D9+C10) -> 501.32643 | E10: =VLOOKUP(B10,'Data & Results'!$O$6:$P$25,2,TRUE) -> 7.3587059 | F10: =SUM(C10*E10)/$D$104 -> 0.060962795
A11: 0.041666667 | B11: 212.71667 | C11: =SUM(B11*0.9) -> 191.445 | D11: =SUM(D10+C11) -> 692.77143 | E11: =VLOOKUP(B11,'Data & Results'!$O$6:$P$25,2,TRUE) -> 6.5474591 | F11: =SUM(C11*E11)/$D$104 -> 0.091266312
A12: 0.052083333 | B12: 156.43 | C12: =SUM(B12*0.9) -> 140.787 | D12: =SUM(D11+C12) -> 833.55843 | E12: =VLOOKUP(B12,'Data & Results'!$O$6:$P$25,2,TRUE) -> 7.0088422 | F12: =SUM(C12*E12)/$D$104 -> 0.071845987
A13: 0.0625 | B13: 140.54333 | C13: =SUM(B13*0.9) -> 126.489 | D13: =SUM(D12+C13) -> 960.04743 | E13: =VLOOKUP(B13,'Data & Results'!$O$6:$P$25,2,TRUE) -> 7.3587059 | F13: =SUM(C13*E13)/$D$104 -> 0.067771623
A14: 0.072916667 | B14: 107.58778 | C14: =SUM(B14*0.9) -> 96.829 | D14: =SUM(D13+C14) -> 1056.8764 | E14: =VLOOKUP(B14,'Data & Results'!$O$6:$P$25,2,TRUE) -> 7.8438161 | F14: =SUM(C14*E14)/$D$104 -> 0.055300178
A15: 0.083333333 | B15: 140.64333 | C15: =SUM(B15*0.9) -> 126.579 | D15: =SUM(D14+C15) -> 1183.4554 | E15: =VLOOKUP(B15,'Data & Results'!$O$6:$P$25,2,TRUE) -> 7.3587059 | F15: =SUM(C15*E15)/$D$104 -> 0.067819844
A16: 0.09375 | B16: 111.66111 | C16: =SUM(B16*0.9) -> 100.495 | D16: =SUM(D15+C16) -> 1283.9504 | E16: =VLOOKUP(B16,'Data & Results'!$O$6:$P$25,2,TRUE) -> 7.8438161 | F16: =SUM(C16*E16)/$D$104 -> 0.057393873
A17: 0.10416667 | B17: 141.98333 | C17: =SUM(B17*0.9) -> 127.785 | D17: =SUM(D16+C17) -> 1411.7354 | E17: =VLOOKUP(B17,'Data & Results'!$O$6:$P$25,2,TRUE) -> 7.3587059 | F17: =SUM(C17*E17)/$D$104 -> 0.068466007
A18: 0.11458333 | B18: 110.87222 | C18: =SUM(B18*0.9) -> 99.785 | D18: =SUM(D17+C18) -> 1511.5204 | E18: =VLOOKUP(B18,'Data & Results'!$O$6:$P$25,2,TRUE) -> 7.8438161 | F18: =SUM(C18*E18)/$D$104 -> 0.056988384
A19: 0.125 | B19: 134.62222 | C19: =SUM(B19*0.9) -> 121.16 | D19: =SUM(D18+C19) -> 1632.6804 | E19: =VLOOKUP(B19,'Data & Results'!$O$6:$P$25,2,TRUE) -> 7.3587059 | F19: =SUM(C19*E19)/$D$104 -> 0.064916394
... A102: 0.98958333 | B102: 349.22 | C102: =SUM(B102*0.9) -> 314.298 | D102: =SUM(D101+C102) -> 13734.293 | E102: =VLOOKUP(B102,'Data & Results'!$O$6:$P$25,2,TRUE) -> 6.0879848 | F102: =SUM(C102*E102)/$D$104 -> 0.13931852
D103: Q (m3) | F103: UQ (±%)
C104: Total | D104: =D102 -> 13734.293 | F104: =SUM(F7:F102) -> 7.0008952

Sheet DWF
A2: DWF | B2: ='Input Data'!D10 -> 171.04167 | C2: l/s
A3: Time | B3: DWF | C3: Flow | E3: Time 2 | F3: Time Real | G3: New Flow | H3: Original
A4: 0 | C4: =B2*1.01724137931034 -> 173.99066 | E4: 0 | F4: 0 | G4: =VLOOKUP(E4,$A$4:$C$28,3,TRUE)+(MOD(E4,1)*(VLOOKUP(ROUNDDOWN(E4,0)+1,$A$4:$C$28,3,TRUE)-VLOOKUP(ROUNDDOWN(E4,0),$A$4:$C$28,3,TRUE))) -> 173.99066 | H4: =VLOOKUP(E4,$A$4:$C$28,3,FALSE) -> 173.99066
A5: 1 | C5: =B2*0.913793103448276 -> 156.2967 | E5: 0.25 | F5: 0.010416667 | G5: =VLOOKUP(E5,$A$4:$C$28,3,TRUE)+(MOD(E5,1)*(VLOOKUP(ROUNDDOWN(E5,0)+1,$A$4:$C$28,3,TRUE)-VLOOKUP(ROUNDDOWN(E5,0),$A$4:$C$28,3,TRUE))) -> 169.56717 | H5: =VLOOKUP(E5,$A$4:$C$28,3,FALSE) -> #N/A
A6: 2 | C6: =B2*0.844827586206897 -> 144.50072 | E6: 0.5 | F6: 0.020833333 | G6: =VLOOKUP(E6,$A$4:$C$28,3,TRUE)+(MOD(E6,1)*(VLOOKUP(ROUNDDOWN(E6,0)+1,$A$4:$C$28,3,TRUE)-VLOOKUP(ROUNDDOWN(E6,0),$A$4:$C$28,3,TRUE))) -> 165.14368 | H6: =VLOOKUP(E6,$A$4:$C$28,3,FALSE) -> #N/A
A7: 3 | C7: =B2*0.612068965517241 -> 104.6893 | E7: 0.75 | F7: 0.03125 | G7: =VLOOKUP(E7,$A$4:$C$28,3,TRUE)+(MOD(E7,1)*(VLOOKUP(ROUNDDOWN(E7,0)+1,$A$4:$C$28,3,TRUE)-VLOOKUP(ROUNDDOWN(E7,0),$A$4:$C$28,3,TRUE))) -> 160.72019 | H7: =VLOOKUP(E7,$A$4:$C$28,3,FALSE) -> #N/A
A8: 4 | C8: =B2*0.543103448275862 -> 92.893319 | E8: 1 | F8: 0.041666667 | G8: =VLOOKUP(E8,$A$4:$C$28,3,TRUE)+(MOD(E8,1)*(VLOOKUP(ROUNDDOWN(E8,0)+1,$A$4:$C$28,3,TRUE)-VLOOKUP(ROUNDDOWN(E8,0),$A$4:$C$28,3,TRUE))) -> 156.2967 | H8: =VLOOKUP(E8,$A$4:$C$28,3,FALSE) -> 156.2967
A9: 5 | C9: =B2*0.551724137931035 -> 94.367816 | E9: 1.25 | F9: 0.052083333 | G9: =VLOOKUP(E9,$A$4:$C$28,3,TRUE)+(MOD(E9,1)*(VLOOKUP(ROUNDDOWN(E9,0)+1,$A$4:$C$28,3,TRUE)-VLOOKUP(ROUNDDOWN(E9,0),$A$4:$C$28,3,TRUE))) -> 153.3477 | H9: =VLOOKUP(E9,$A$4:$C$28,3,FALSE) -> #N/A
A10: 6 | C10: =B2*0.603448275862069 -> 103.2148 | E10: 1.5 | F10: 0.0625 | G10: =VLOOKUP(E10,$A$4:$C$28,3,TRUE)+(MOD(E10,1)*(VLOOKUP(ROUNDDOWN(E10,0)+1,$A$4:$C$28,3,TRUE)-VLOOKUP(ROUNDDOWN(E10,0),$A$4:$C$28,3,TRUE))) -> 150.39871 | H10: =VLOOKUP(E10,$A$4:$C$28,3,FALSE) -> #N/A
A11: 7 | C11: =B2*0.913793103448276 -> 156.2967 | E11: 1.75 | F11: 0.072916667 | G11: =VLOOKUP(E11,$A$4:$C$28,3,TRUE)+(MOD(E11,1)*(VLOOKUP(ROUNDDOWN(E11,0)+1,$A$4:$C$28,3,TRUE)-VLOOKUP(ROUNDDOWN(E11,0),$A$4:$C$28,3,TRUE))) -> 147.44971 | H11: =VLOOKUP(E11,$A$4:$C$28,3,FALSE) -> #N/A
A12: 8 | C12: =B2*1.4051724137931 -> 240.34303 | E12: 2 | F12: 0.083333333 | G12: =VLOOKUP(E12,$A$4:$C$28,3,TRUE)+(MOD(E12,1)*(VLOOKUP(ROUNDDOWN(E12,0)+1,$A$4:$C$28,3,TRUE)-VLOOKUP(ROUNDDOWN(E12,0),$A$4:$C$28,3,TRUE))) -> 144.50072 | H12: =VLOOKUP(E12,$A$4:$C$28,3,FALSE) -> 144.50072
A13: 9 | C13: =B2*1.54310344827586 -> 263.93499 | E13: 2.25 | F13: 0.09375 | G13: =VLOOKUP(E13,$A$4:$C$28,3,TRUE)+(MOD(E13,1)*(VLOOKUP(ROUNDDOWN(E13,0)+1,$A$4:$C$28,3,TRUE)-VLOOKUP(ROUNDDOWN(E13,0),$A$4:$C$28,3,TRUE))) -> 134.54786 | H13: =VLOOKUP(E13,$A$4:$C$28,3,FALSE) -> #N/A
A14: 10 | C14: =B2*1.41379310344828 -> 241.81753 | E14: 2.5 | F14: 0.10416667 | G14: =VLOOKUP(E14,$A$4:$C$28,3,TRUE)+(MOD(E14,1)*(VLOOKUP(ROUNDDOWN(E14,0)+1,$A$4:$C$28,3,TRUE)-VLOOKUP(ROUNDDOWN(E14,0),$A$4:$C$28,3,TRUE))) -> 124.59501 | H14: =VLOOKUP(E14,$A$4:$C$28,3,FALSE) -> #N/A
A15: 11 | C15: =B2*1.2586207 -> 215.27658 | E15: 2.75 | F15: 0.11458333 | G15: =VLOOKUP(E15,$A$4:$C$28,3,TRUE)+(MOD(E15,1)*(VLOOKUP(ROUNDDOWN(E15,0)+1,$A$4:$C$28,3,TRUE)-VLOOKUP(ROUNDDOWN(E15,0),$A$4:$C$28,3,TRUE))) -> 114.64215 | H15: =VLOOKUP(E15,$A$4:$C$28,3,FALSE) -> #N/A
A16: 12 | C16: =B2*1.0948275862069 -> 187.26114 | E16: 3 | F16: 0.125 | G16: =VLOOKUP(E16,$A$4:$C$28,3,TRUE)+(MOD(E16,1)*(VLOOKUP(ROUNDDOWN(E16,0)+1,$A$4:$C$28,3,TRUE)-VLOOKUP(ROUNDDOWN(E16,0),$A$4:$C$28,3,TRUE))) -> 104.6893 | H16: =VLOOKUP(E16,$A$4:$C$28,3,FALSE) -> 104.6893
A17: 13 | C17: =B2*0.96551724137931 -> 165.14368 | E17: 3.25 | F17: 0.13541667 | G17: =VLOOKUP(E17,$A$4:$C$28,3,TRUE)+(MOD(E17,1)*(VLOOKUP(ROUNDDOWN(E17,0)+1,$A$4:$C$28,3,TRUE)-VLOOKUP(ROUNDDOWN(E17,0),$A$4:$C$28,3,TRUE))) -> 101.7403 | H17: =VLOOKUP(E17,$A$4:$C$28,3,FALSE) -> #N/A
A18: 14 | C18: =B2*0.879310344827586 -> 150.39871 | E18: 3.5 | F18: 0.14583333 | G18: =VLOOKUP(E18,$A$4:$C$28,3,TRUE)+(MOD(E18,1)*(VLOOKUP(ROUNDDOWN(E18,0)+1,$A$4:$C$28,3,TRUE)-VLOOKUP(ROUNDDOWN(E18,0),$A$4:$C$28,3,TRUE))) -> 98.791307 | H18: =VLOOKUP(E18,$A$4:$C$28,3,FALSE) -> #N/A
A19: 15 | C19: =B2*0.862068965517241 -> 147.44971 | E19: 3.75 | F19: 0.15625 | G19: =VLOOKUP(E19,$A$4:$C$28,3,TRUE)+(MOD(E19,1)*(VLOOKUP(ROUNDDOWN(E19,0)+1,$A$4:$C$28,3,TRUE)-VLOOKUP(ROUNDDOWN(E19,0),$A$4:$C$28,3,TRUE))) -> 95.842313 | H19: =VLOOKUP(E19,$A$4:$C$28,3,FALSE) -> #N/A
A20: 16 | C20: =B2*0.905172413793104 -> 154.8222 | E20: 4 | F20: 0.16666667 | G20: =VLOOKUP(E20,$A$4:$C$28,3,TRUE)+(MOD(E20,1)*(VLOOKUP(ROUNDDOWN(E20,0)+1,$A$4:$C$28,3,TRUE)-VLOOKUP(ROUNDDOWN(E20,0),$A$4:$C$28,3,TRUE))) -> 92.893319 | H20: =VLOOKUP(E20,$A$4:$C$28,3,FALSE) -> 92.893319
A21: 17 | C21: =B2*1.01724137931034 -> 173.99066 | E21: 4.25 | F21: 0.17708333 | G21: =VLOOKUP(E21,$A$4:$C$28,3,TRUE)+(MOD(E21,1)*(VLOOKUP(ROUNDDOWN(E21,0)+1,$A$4:$C$28,3,TRUE)-VLOOKUP(ROUNDDOWN(E21,0),$A$4:$C$28,3,TRUE))) -> 93.261943 | H21: =VLOOKUP(E21,$A$4:$C$28,3,FALSE) -> #N/A
A22: 18 | C22: =B2*1.1551724137931 -> 197.58261 | E22: 4.5 | F22: 0.1875 | G22: =VLOOKUP(E22,$A$4:$C$28,3,TRUE)+(MOD(E22,1)*(VLOOKUP(ROUNDDOWN(E22,0)+1,$A$4:$C$28,3,TRUE)-VLOOKUP(ROUNDDOWN(E22,0),$A$4:$C$28,3,TRUE))) -> 93.630568 | H22: =VLOOKUP(E22,$A$4:$C$28,3,FALSE) -> #N/A
A23: 19 | C23: =B2*1.23275862068966 -> 210.85309 | E23: 4.75 | F23: 0.19791667 | G23: =VLOOKUP(E23,$A$4:$C$28,3,TRUE)+(MOD(E23,1)*(VLOOKUP(ROUNDDOWN(E23,0)+1,$A$4:$C$28,3,TRUE)-VLOOKUP(ROUNDDOWN(E23,0),$A$4:$C$28,3,TRUE))) -> 93.999192 | H23: =VLOOKUP(E23,$A$4:$C$28,3,FALSE) -> #N/A
A24: 20 | C24: =B2*1.23275862068966 -> 210.85309 | E24: 5 | F24: 0.20833333 | G24: =VLOOKUP(E24,$A$4:$C$28,3,TRUE)+(MOD(E24,1)*(VLOOKUP(ROUNDDOWN(E24,0)+1,$A$4:$C$28,3,TRUE)-VLOOKUP(ROUNDDOWN(E24,0),$A$4:$C$28,3,TRUE))) -> 94.367816 | H24: =VLOOKUP(E24,$A$4:$C$28,3,FALSE) -> 94.367816
A25: 21 | C25: =B2*1.17241379310345 -> 200.53161 | E25: 5.25 | F25: 0.21875 | G25: =VLOOKUP(E25,$A$4:$C$28,3,TRUE)+(MOD(E25,1)*(VLOOKUP(ROUNDDOWN(E25,0)+1,$A$4:$C$28,3,TRUE)-VLOOKUP(ROUNDDOWN(E25,0),$A$4:$C$28,3,TRUE))) -> 96.579562 | H25: =VLOOKUP(E25,$A$4:$C$28,3,FALSE) -> #N/A
A26: 22 | C26: =B2*1.18103448275862 -> 202.00611 | E26: 5.5 | F26: 0.22916667 | G26: =VLOOKUP(E26,$A$4:$C$28,3,TRUE)+(MOD(E26,1)*(VLOOKUP(ROUNDDOWN(E26,0)+1,$A$4:$C$28,3,TRUE)-VLOOKUP(ROUNDDOWN(E26,0),$A$4:$C$28,3,TRUE))) -> 98.791307 | H26: =VLOOKUP(E26,$A$4:$C$28,3,FALSE) -> #N/A
A27: 23 | C27: =B2*1.10344827586207 -> 188.73563 | E27: 5.75 | F27: 0.23958333 | G27: =VLOOKUP(E27,$A$4:$C$28,3,TRUE)+(MOD(E27,1)*(VLOOKUP(ROUNDDOWN(E27,0)+1,$A$4:$C$28,3,TRUE)-VLOOKUP(ROUNDDOWN(E27,0),$A$4:$C$28,3,TRUE))) -> 101.00305 | H27: =VLOOKUP(E27,$A$4:$C$28,3,FALSE) -> #N/A
A28: 24 | C28: =B2*1.01724137931034 -> 173.99066 | E28: 6 | F28: 0.25 | G28: =VLOOKUP(E28,$A$4:$C$28,3,TRUE)+(MOD(E28,1)*(VLOOKUP(ROUNDDOWN(E28,0)+1,$A$4:$C$28,3,TRUE)-VLOOKUP(ROUNDDOWN(E28,0),$A$4:$C$28,3,TRUE))) -> 103.2148 | H28: =VLOOKUP(E28,$A$4:$C$28,3,FALSE) -> 103.2148
E29: 6.25 | F29: 0.26041667 | G29: =VLOOKUP(E29,$A$4:$C$28,3,TRUE)+(MOD(E29,1)*(VLOOKUP(ROUNDDOWN(E29,0)+1,$A$4:$C$28,3,TRUE)-VLOOKUP(ROUNDDOWN(E29,0),$A$4:$C$28,3,TRUE))) -> 116.48527 | H29: =VLOOKUP(E29,$A$4:$C$28,3,FALSE) -> #N/A
E30: 6.5 | F30: 0.27083333 | G30: =VLOOKUP(E30,$A$4:$C$28,3,TRUE)+(MOD(E30,1)*(VLOOKUP(ROUNDDOWN(E30,0)+1,$A$4:$C$28,3,TRUE)-VLOOKUP(ROUNDDOWN(E30,0),$A$4:$C$28,3,TRUE))) -> 129.75575 | H30: =VLOOKUP(E30,$A$4:$C$28,3,FALSE) -> #N/A
E31: 6.75 | F31: 0.28125 | G31: =VLOOKUP(E31,$A$4:$C$28,3,TRUE)+(MOD(E31,1)*(VLOOKUP(ROUNDDOWN(E31,0)+1,$A$4:$C$28,3,TRUE)-VLOOKUP(ROUNDDOWN(E31,0),$A$4:$C$28,3,TRUE))) -> 143.02622 | H31: =VLOOKUP(E31,$A$4:$C$28,3,FALSE) -> #N/A
E32: 7 | F32: 0.29166667 | G32: =VLOOKUP(E32,$A$4:$C$28,3,TRUE)+(MOD(E32,1)*(VLOOKUP(ROUNDDOWN(E32,0)+1,$A$4:$C$28,3,TRUE)-VLOOKUP(ROUNDDOWN(E32,0),$A$4:$C$28,3,TRUE))) -> 156.2967 | H32: =VLOOKUP(E32,$A$4:$C$28,3,FALSE) -> 156.2967
E33: 7.25 | F33: 0.30208333 | G33: =VLOOKUP(E33,$A$4:$C$28,3,TRUE)+(MOD(E33,1)*(VLOOKUP(ROUNDDOWN(E33,0)+1,$A$4:$C$28,3,TRUE)-VLOOKUP(ROUNDDOWN(E33,0),$A$4:$C$28,3,TRUE))) -> 177.30828 | H33: =VLOOKUP(E33,$A$4:$C$28,3,FALSE) -> #N/A
E34: 7.5 | F34: 0.3125 | G34: =VLOOKUP(E34,$A$4:$C$28,3,TRUE)+(MOD(E34,1)*(VLOOKUP(ROUNDDOWN(E34,0)+1,$A$4:$C$28,3,TRUE)-VLOOKUP(ROUNDDOWN(E34,0),$A$4:$C$28,3,TRUE))) -> 198.31986 | H34: =VLOOKUP(E34,$A$4:$C$28,3,FALSE) -> #N/A
E35: 7.75 | F35: 0.32291667 | G35: =VLOOKUP(E35,$A$4:$C$28,3,TRUE)+(MOD(E35,1)*(VLOOKUP(ROUNDDOWN(E35,0)+1,$A$4:$C$28,3,TRUE)-VLOOKUP(ROUNDDOWN(E35,0),$A$4:$C$28,3,TRUE))) -> 219.33145 | H35: =VLOOKUP(E35,$A$4:$C$28,3,FALSE) -> #N/A
E36: 8 | F36: 0.33333333 | G36: =VLOOKUP(E36,$A$4:$C$28,3,TRUE)+(MOD(E36,1)*(VLOOKUP(ROUNDDOWN(E36,0)+1,$A$4:$C$28,3,TRUE)-VLOOKUP(ROUNDDOWN(E36,0),$A$4:$C$28,3,TRUE))) -> 240.34303 | H36: =VLOOKUP(E36,$A$4:$C$28,3,FALSE) -> 240.34303
E37: 8.25 | F37: 0.34375 | G37: =VLOOKUP(E37,$A$4:$C$28,3,TRUE)+(MOD(E37,1)*(VLOOKUP(ROUNDDOWN(E37,0)+1,$A$4:$C$28,3,TRUE)-VLOOKUP(ROUNDDOWN(E37,0),$A$4:$C$28,3,TRUE))) -> 246.24102 | H37: =VLOOKUP(E37,$A$4:$C$28,3,FALSE) -> #N/A
E38: 8.5 | F38: 0.35416667 | G38: =VLOOKUP(E38,$A$4:$C$28,3,TRUE)+(MOD(E38,1)*(VLOOKUP(ROUNDDOWN(E38,0)+1,$A$4:$C$28,3,TRUE)-VLOOKUP(ROUNDDOWN(E38,0),$A$4:$C$28,3,TRUE))) -> 252.13901 | H38: =VLOOKUP(E38,$A$4:$C$28,3,FALSE) -> #N/A
E39: 8.75 | F39: 0.36458333 | G39: =VLOOKUP(E39,$A$4:$C$28,3,TRUE)+(MOD(E39,1)*(VLOOKUP(ROUNDDOWN(E39,0)+1,$A$4:$C$28,3,TRUE)-VLOOKUP(ROUNDDOWN(E39,0),$A$4:$C$28,3,TRUE))) -> 258.037 | H39: =VLOOKUP(E39,$A$4:$C$28,3,FALSE) -> #N/A
E40: 9 | F40: 0.375 | G40: =VLOOKUP(E40,$A$4:$C$28,3,TRUE)+(MOD(E40,1)*(VLOOKUP(ROUNDDOWN(E40,0)+1,$A$4:$C$28,3,TRUE)-VLOOKUP(ROUNDDOWN(E40,0),$A$4:$C$28,3,TRUE))) -> 263.93499 | H40: =VLOOKUP(E40,$A$4:$C$28,3,FALSE) -> 263.93499
... E99: 23.75 | F99: 0.98958333 | G99: =VLOOKUP(E99,$A$4:$C$28,3,TRUE)+(MOD(E99,1)*(VLOOKUP(ROUNDDOWN(E99,0)+1,$A$4:$C$28,3,TRUE)-VLOOKUP(ROUNDDOWN(E99,0),$A$4:$C$28,3,TRUE))) -> 177.6769 | H99: =VLOOKUP(E99,$A$4:$C$28,3,FALSE) -> #N/A

Sheet DWF Uncertainty
A3: Time | B3: Average | C3: 15min | D3: Total | E3: Uncertainty | F3: Contributions
B4: Flow | C4: Volume | D4: Volume | F4: to the
F5: Uncertainty in
B6: (l/s) | C6: (m3) | D6: (m3) | E6: (±%) | F6: TDV (±%)
A7: 0 | B7: =DWF!G4 -> 173.99066 | C7: =SUM(B7*0.9) -> 156.59159 | D7: =SUM(C7) -> 156.59159 | E7: =VLOOKUP(B7,'Data & Results'!$O$6:$P$25,2,TRUE) -> 6.7475847 | F7: =SUM(C7*E7)/$D$104 -> 0.07026253
A8: 0.010416667 | B8: =DWF!G5 -> 169.56717 | C8: =SUM(B8*0.9) -> 152.61045 | D8: =SUM(D7+C8) -> 309.20205 | E8: =VLOOKUP(B8,'Data & Results'!$O$6:$P$25,2,TRUE) -> 7.0088422 | F8: =SUM(C8*E8)/$D$104 -> 0.071127502
A9: 0.020833333 | B9: =DWF!G6 -> 165.14368 | C9: =SUM(B9*0.9) -> 148.62931 | D9: =SUM(D8+C9) -> 457.83136 | E9: =VLOOKUP(B9,'Data & Results'!$O$6:$P$25,2,TRUE) -> 7.0088422 | F9: =SUM(C9*E9)/$D$104 -> 0.069272002
A10: 0.03125 | B10: =DWF!G7 -> 160.72019 | C10: =SUM(B10*0.9) -> 144.64817 | D10: =SUM(D9+C10) -> 602.47953 | E10: =VLOOKUP(B10,'Data & Results'!$O$6:$P$25,2,TRUE) -> 7.0088422 | F10: =SUM(C10*E10)/$D$104 -> 0.067416502
A11: 0.041666667 | B11: =DWF!G8 -> 156.2967 | C11: =SUM(B11*0.9) -> 140.66703 | D11: =SUM(D10+C11) -> 743.14655 | E11: =VLOOKUP(B11,'Data & Results'!$O$6:$P$25,2,TRUE) -> 7.0088422 | F11: =SUM(C11*E11)/$D$104 -> 0.065561002
A12: 0.052083333 | B12: =DWF!G9 -> 153.3477 | C12: =SUM(B12*0.9) -> 138.01293 | D12: =SUM(D11+C12) -> 881.15948 | E12: =VLOOKUP(B12,'Data & Results'!$O$6:$P$25,2,TRUE) -> 7.0088422 | F12: =SUM(C12*E12)/$D$104 -> 0.064324002
A13: 0.0625 | B13: =DWF!G10 -> 150.39871 | C13: =SUM(B13*0.9) -> 135.35884 | D13: =SUM(D12+C13) -> 1016.5183 | E13: =VLOOKUP(B13,'Data & Results'!$O$6:$P$25,2,TRUE) -> 7.0088422 | F13: =SUM(C13*E13)/$D$104 -> 0.063087002
A14: 0.072916667 | B14: =DWF!G11 -> 147.44971 | C14: =SUM(B14*0.9) -> 132.70474 | D14: =SUM(D13+C14) -> 1149.2231 | E14: =VLOOKUP(B14,'Data & Results'!$O$6:$P$25,2,TRUE) -> 7.0088422 | F14: =SUM(C14*E14)/$D$104 -> 0.061850002
A15: 0.083333333 | B15: =DWF!G12 -> 144.50072 | C15: =SUM(B15*0.9) -> 130.05065 | D15: =SUM(D14+C15) -> 1279.2737 | E15: =VLOOKUP(B15,'Data & Results'!$O$6:$P$25,2,TRUE) -> 7.3587059 | F15: =SUM(C15*E15)/$D$104 -> 0.06363865
A16: 0.09375 | B16: =DWF!G13 -> 134.54786 | C16: =SUM(B16*0.9) -> 121.09308 | D16: =SUM(D15+C16) -> 1400.3668 | E16: =VLOOKUP(B16,'Data & Results'!$O$6:$P$25,2,TRUE) -> 7.3587059 | F16: =SUM(C16*E16)/$D$104 -> 0.059255375
A17: 0.10416667 | B17: =DWF!G14 -> 124.59501 | C17: =SUM(B17*0.9) -> 112.13551 | D17: =SUM(D16+C17) -> 1512.5023 | E17: =VLOOKUP(B17,'Data & Results'!$O$6:$P$25,2,TRUE) -> 7.3587059 | F17: =SUM(C17*E17)/$D$104 -> 0.054872101
A18: 0.11458333 | B18: =DWF!G15 -> 114.64215 | C18: =SUM(B18*0.9) -> 103.17794 | D18: =SUM(D17+C18) -> 1615.6802 | E18: =VLOOKUP(B18,'Data & Results'!$O$6:$P$25,2,TRUE) -> 7.8438161 | F18: =SUM(C18*E18)/$D$104 -> 0.053817217
A19: 0.125 | B19: =DWF!G16 -> 104.6893 | C19: =SUM(B19*0.9) -> 94.220366 | D19: =SUM(D18+C19) -> 1709.9006 | E19: =VLOOKUP(B19,'Data & Results'!$O$6:$P$25,2,TRUE) -> 7.8438161 | F19: =SUM(C19*E19)/$D$104 -> 0.049144983
... A102: 0.98958333 | B102: =DWF!G99 -> 177.6769 | C102: =SUM(B102*0.9) -> 159.90921 | D102: =SUM(D101+C102) -> 15038.101 | E102: =VLOOKUP(B102,'Data & Results'!$O$6:$P$25,2,TRUE) -> 6.7475847 | F102: =SUM(C102*E102)/$D$104 -> 0.071751143
D103: Q (m3) | F103: UQ (±%)
C104: Total | D104: =D102 -> 15038.101 | F104: =SUM(F7:F102) -> 6.833744

Sheet FFT
A2: DWF | B2: ='Input Data'!D9 -> 365.47454 | C2: l/s
A3: Time | B3: DWF | C3: Flow | E3: Time 2 | F3: Time Real | G3: New Flow | H3: Original
A4: 0 | C4: =B2*1.01724137931034 -> 371.77582 | E4: 0 | F4: 0 | G4: =VLOOKUP(E4,$A$4:$C$28,3,TRUE)+(MOD(E4,1)*(VLOOKUP(ROUNDDOWN(E4,0)+1,$A$4:$C$28,3,TRUE)-VLOOKUP(ROUNDDOWN(E4,0),$A$4:$C$28,3,TRUE))) -> 371.77582 | H4: =VLOOKUP(E4,$A$4:$C$28,3,FALSE) -> 371.77582
A5: 1 | C5: =B2*0.913793103448276 -> 333.96811 | E5: 0.25 | F5: 0.010416667 | G5: =VLOOKUP(E5,$A$4:$C$28,3,TRUE)+(MOD(E5,1)*(VLOOKUP(ROUNDDOWN(E5,0)+1,$A$4:$C$28,3,TRUE)-VLOOKUP(ROUNDDOWN(E5,0),$A$4:$C$28,3,TRUE))) -> 362.32389 | H5: =VLOOKUP(E5,$A$4:$C$28,3,FALSE) -> #N/A
A6: 2 | C6: =B2*0.844827586206897 -> 308.76297 | E6: 0.5 | F6: 0.020833333 | G6: =VLOOKUP(E6,$A$4:$C$28,3,TRUE)+(MOD(E6,1)*(VLOOKUP(ROUNDDOWN(E6,0)+1,$A$4:$C$28,3,TRUE)-VLOOKUP(ROUNDDOWN(E6,0),$A$4:$C$28,3,TRUE))) -> 352.87197 | H6: =VLOOKUP(E6,$A$4:$C$28,3,FALSE) -> #N/A
A7: 3 | C7: =B2*0.612068965517241 -> 223.69562 | E7: 0.75 | F7: 0.03125 | G7: =VLOOKUP(E7,$A$4:$C$28,3,TRUE)+(MOD(E7,1)*(VLOOKUP(ROUNDDOWN(E7,0)+1,$A$4:$C$28,3,TRUE)-VLOOKUP(ROUNDDOWN(E7,0),$A$4:$C$28,3,TRUE))) -> 343.42004 | H7: =VLOOKUP(E7,$A$4:$C$28,3,FALSE) -> #N/A
A8: 4 | C8: =B2*0.543103448275862 -> 198.49048 | E8: 1 | F8: 0.041666667 | G8: =VLOOKUP(E8,$A$4:$C$28,3,TRUE)+(MOD(E8,1)*(VLOOKUP(ROUNDDOWN(E8,0)+1,$A$4:$C$28,3,TRUE)-VLOOKUP(ROUNDDOWN(E8,0),$A$4:$C$28,3,TRUE))) -> 333.96811 | H8: =VLOOKUP(E8,$A$4:$C$28,3,FALSE) -> 333.96811
A9: 5 | C9: =B2*0.551724137931035 -> 201.64112 | E9: 1.25 | F9: 0.052083333 | G9: =VLOOKUP(E9,$A$4:$C$28,3,TRUE)+(MOD(E9,1)*(VLOOKUP(ROUNDDOWN(E9,0)+1,$A$4:$C$28,3,TRUE)-VLOOKUP(ROUNDDOWN(E9,0),$A$4:$C$28,3,TRUE))) -> 327.66683 | H9: =VLOOKUP(E9,$A$4:$C$28,3,FALSE) -> #N/A
A10: 6 | C10: =B2*0.603448275862069 -> 220.54498 | E10: 1.5 | F10: 0.0625 | G10: =VLOOKUP(E10,$A$4:$C$28,3,TRUE)+(MOD(E10,1)*(VLOOKUP(ROUNDDOWN(E10,0)+1,$A$4:$C$28,3,TRUE)-VLOOKUP(ROUNDDOWN(E10,0),$A$4:$C$28,3,TRUE))) -> 321.36554 | H10: =VLOOKUP(E10,$A$4:$C$28,3,FALSE) -> #N/A
A11: 7 | C11: =B2*0.913793103448276 -> 333.96811 | E11: 1.75 | F11: 0.072916667 | G11: =VLOOKUP(E11,$A$4:$C$28,3,TRUE)+(MOD(E11,1)*(VLOOKUP(ROUNDDOWN(E11,0)+1,$A$4:$C$28,3,TRUE)-VLOOKUP(ROUNDDOWN(E11,0),$A$4:$C$28,3,TRUE))) -> 315.06426 | H11: =VLOOKUP(E11,$A$4:$C$28,3,FALSE) -> #N/A
A12: 8 | C12: =B2*1.4051724137931 -> 513.55474 | E12: 2 | F12: 0.083333333 | G12: =VLOOKUP(E12,$A$4:$C$28,3,TRUE)+(MOD(E12,1)*(VLOOKUP(ROUNDDOWN(E12,0)+1,$A$4:$C$28,3,TRUE)-VLOOKUP(ROUNDDOWN(E12,0),$A$4:$C$28,3,TRUE))) -> 308.76297 | H12: =VLOOKUP(E12,$A$4:$C$28,3,FALSE) -> 308.76297
A13: 9 | C13: =B2*1.54310344827586 -> 563.96502 | E13: 2.25 | F13: 0.09375 | G13: =VLOOKUP(E13,$A$4:$C$28,3,TRUE)+(MOD(E13,1)*(VLOOKUP(ROUNDDOWN(E13,0)+1,$A$4:$C$28,3,TRUE)-VLOOKUP(ROUNDDOWN(E13,0),$A$4:$C$28,3,TRUE))) -> 287.49613 | H13: =VLOOKUP(E13,$A$4:$C$28,3,FALSE) -> #N/A
A14: 10 | C14: =B2*1.41379310344828 -> 516.70538 | E14: 2.5 | F14: 0.10416667 | G14: =VLOOKUP(E14,$A$4:$C$28,3,TRUE)+(MOD(E14,1)*(VLOOKUP(ROUNDDOWN(E14,0)+1,$A$4:$C$28,3,TRUE)-VLOOKUP(ROUNDDOWN(E14,0),$A$4:$C$28,3,TRUE))) -> 266.2293 | H14: =VLOOKUP(E14,$A$4:$C$28,3,FALSE) -> #N/A
A15: 11 | C15: =B2*1.2586207 -> 459.99382 | E15: 2.75 | F15: 0.11458333 | G15: =VLOOKUP(E15,$A$4:$C$28,3,TRUE)+(MOD(E15,1)*(VLOOKUP(ROUNDDOWN(E15,0)+1,$A$4:$C$28,3,TRUE)-VLOOKUP(ROUNDDOWN(E15,0),$A$4:$C$28,3,TRUE))) -> 244.96246 | H15: =VLOOKUP(E15,$A$4:$C$28,3,FALSE) -> #N/A
A16: 12 | C16: =B2*1.0948275862069 -> 400.13161 | E16: 3 | F16: 0.125 | G16: =VLOOKUP(E16,$A$4:$C$28,3,TRUE)+(MOD(E16,1)*(VLOOKUP(ROUNDDOWN(E16,0)+1,$A$4:$C$28,3,TRUE)-VLOOKUP(ROUNDDOWN(E16,0),$A$4:$C$28,3,TRUE))) -> 223.69562 | H16: =VLOOKUP(E16,$A$4:$C$28,3,FALSE) -> 223.69562
A17: 13 | C17: =B2*0.96551724137931 -> 352.87197 | E17: 3.25 | F17: 0.13541667 | G17: =VLOOKUP(E17,$A$4:$C$28,3,TRUE)+(MOD(E17,1)*(VLOOKUP(ROUNDDOWN(E17,0)+1,$A$4:$C$28,3,TRUE)-VLOOKUP(ROUNDDOWN(E17,0),$A$4:$C$28,3,TRUE))) -> 217.39434 | H17: =VLOOKUP(E17,$A$4:$C$28,3,FALSE) -> #N/A
A18: 14 | C18: =B2*0.879310344827586 -> 321.36554 | E18: 3.5 | F18: 0.14583333 | G18: =VLOOKUP(E18,$A$4:$C$28,3,TRUE)+(MOD(E18,1)*(VLOOKUP(ROUNDDOWN(E18,0)+1,$A$4:$C$28,3,TRUE)-VLOOKUP(ROUNDDOWN(E18,0),$A$4:$C$28,3,TRUE))) -> 211.09305 | H18: =VLOOKUP(E18,$A$4:$C$28,3,FALSE) -> #N/A
A19: 15 | C19: =B2*0.862068965517241 -> 315.06426 | E19: 3.75 | F19: 0.15625 | G19: =VLOOKUP(E19,$A$4:$C$28,3,TRUE)+(MOD(E19,1)*(VLOOKUP(ROUNDDOWN(E19,0)+1,$A$4:$C$28,3,TRUE)-VLOOKUP(ROUNDDOWN(E19,0),$A$4:$C$28,3,TRUE))) -> 204.79177 | H19: =VLOOKUP(E19,$A$4:$C$28,3,FALSE) -> #N/A
A20: 16 | C20: =B2*0.905172413793104 -> 330.81747 | E20: 4 | F20: 0.16666667 | G20: =VLOOKUP(E20,$A$4:$C$28,3,TRUE)+(MOD(E20,1)*(VLOOKUP(ROUNDDOWN(E20,0)+1,$A$4:$C$28,3,TRUE)-VLOOKUP(ROUNDDOWN(E20,0),$A$4:$C$28,3,TRUE))) -> 198.49048 | H20: =VLOOKUP(E20,$A$4:$C$28,3,FALSE) -> 198.49048
A21: 17 | C21: =B2*1.01724137931034 -> 371.77582 | E21: 4.25 | F21: 0.17708333 | G21: =VLOOKUP(E21,$A$4:$C$28,3,TRUE)+(MOD(E21,1)*(VLOOKUP(ROUNDDOWN(E21,0)+1,$A$4:$C$28,3,TRUE)-VLOOKUP(ROUNDDOWN(E21,0),$A$4:$C$28,3,TRUE))) -> 199.27814 | H21: =VLOOKUP(E21,$A$4:$C$28,3,FALSE) -> #N/A
A22: 18 | C22: =B2*1.1551724137931 -> 422.1861 | E22: 4.5 | F22: 0.1875 | G22: =VLOOKUP(E22,$A$4:$C$28,3,TRUE)+(MOD(E22,1)*(VLOOKUP(ROUNDDOWN(E22,0)+1,$A$4:$C$28,3,TRUE)-VLOOKUP(ROUNDDOWN(E22,0),$A$4:$C$28,3,TRUE))) -> 200.0658 | H22: =VLOOKUP(E22,$A$4:$C$28,3,FALSE) -> #N/A
A23: 19 | C23: =B2*1.23275862068966 -> 450.54189 | E23: 4.75 | F23: 0.19791667 | G23: =VLOOKUP(E23,$A$4:$C$28,3,TRUE)+(MOD(E23,1)*(VLOOKUP(ROUNDDOWN(E23,0)+1,$A$4:$C$28,3,TRUE)-VLOOKUP(ROUNDDOWN(E23,0),$A$4:$C$28,3,TRUE))) -> 200.85346 | H23: =VLOOKUP(E23,$A$4:$C$28,3,FALSE) -> #N/A
A24: 20 | C24: =B2*1.23275862068966 -> 450.54189 | E24: 5 | F24: 0.20833333 | G24: =VLOOKUP(E24,$A$4:$C$28,3,TRUE)+(MOD(E24,1)*(VLOOKUP(ROUNDDOWN(E24,0)+1,$A$4:$C$28,3,TRUE)-VLOOKUP(ROUNDDOWN(E24,0),$A$4:$C$28,3,TRUE))) -> 201.64112 | H24: =VLOOKUP(E24,$A$4:$C$28,3,FALSE) -> 201.64112
A25: 21 | C25: =B2*1.17241379310345 -> 428.48739 | E25: 5.25 | F25: 0.21875 | G25: =VLOOKUP(E25,$A$4:$C$28,3,TRUE)+(MOD(E25,1)*(VLOOKUP(ROUNDDOWN(E25,0)+1,$A$4:$C$28,3,TRUE)-VLOOKUP(ROUNDDOWN(E25,0),$A$4:$C$28,3,TRUE))) -> 206.36709 | H25: =VLOOKUP(E25,$A$4:$C$28,3,FALSE) -> #N/A
A26: 22 | C26: =B2*1.18103448275862 -> 431.63803 | E26: 5.5 | F26: 0.22916667 | G26: =VLOOKUP(E26,$A$4:$C$28,3,TRUE)+(MOD(E26,1)*(VLOOKUP(ROUNDDOWN(E26,0)+1,$A$4:$C$28,3,TRUE)-VLOOKUP(ROUNDDOWN(E26,0),$A$4:$C$28,3,TRUE))) -> 211.09305 | H26: =VLOOKUP(E26,$A$4:$C$28,3,FALSE) -> #N/A
A27: 23 | C27: =B2*1.10344827586207 -> 403.28225 | E27: 5.75 | F27: 0.23958333 | G27: =VLOOKUP(E27,$A$4:$C$28,3,TRUE)+(MOD(E27,1)*(VLOOKUP(ROUNDDOWN(E27,0)+1,$A$4:$C$28,3,TRUE)-VLOOKUP(ROUNDDOWN(E27,0),$A$4:$C$28,3,TRUE))) -> 215.81902 | H27: =VLOOKUP(E27,$A$4:$C$28,3,FALSE) -> #N/A
A28: 24 | C28: =B2*1.01724137931034 -> 371.77582 | E28: 6 | F28: 0.25 | G28: =VLOOKUP(E28,$A$4:$C$28,3,TRUE)+(MOD(E28,1)*(VLOOKUP(ROUNDDOWN(E28,0)+1,$A$4:$C$28,3,TRUE)-VLOOKUP(ROUNDDOWN(E28,0),$A$4:$C$28,3,TRUE))) -> 220.54498 | H28: =VLOOKUP(E28,$A$4:$C$28,3,FALSE) -> 220.54498
E29: 6.25 | F29: 0.26041667 | G29: =VLOOKUP(E29,$A$4:$C$28,3,TRUE)+(MOD(E29,1)*(VLOOKUP(ROUNDDOWN(E29,0)+1,$A$4:$C$28,3,TRUE)-VLOOKUP(ROUNDDOWN(E29,0),$A$4:$C$28,3,TRUE))) -> 248.90076 | H29: =VLOOKUP(E29,$A$4:$C$28,3,FALSE) -> #N/A
E30: 6.5 | F30: 0.27083333 | G30: =VLOOKUP(E30,$A$4:$C$28,3,TRUE)+(MOD(E30,1)*(VLOOKUP(ROUNDDOWN(E30,0)+1,$A$4:$C$28,3,TRUE)-VLOOKUP(ROUNDDOWN(E30,0),$A$4:$C$28,3,TRUE))) -> 277.25655 | H30: =VLOOKUP(E30,$A$4:$C$28,3,FALSE) -> #N/A
E31: 6.75 | F31: 0.28125 | G31: =VLOOKUP(E31,$A$4:$C$28,3,TRUE)+(MOD(E31,1)*(VLOOKUP(ROUNDDOWN(E31,0)+1,$A$4:$C$28,3,TRUE)-VLOOKUP(ROUNDDOWN(E31,0),$A$4:$C$28,3,TRUE))) -> 305.61233 | H31: =VLOOKUP(E31,$A$4:$C$28,3,FALSE) -> #N/A
E32: 7 | F32: 0.29166667 | G32: =VLOOKUP(E32,$A$4:$C$28,3,TRUE)+(MOD(E32,1)*(VLOOKUP(ROUNDDOWN(E32,0)+1,$A$4:$C$28,3,TRUE)-VLOOKUP(ROUNDDOWN(E32,0),$A$4:$C$28,3,TRUE))) -> 333.96811 | H32: =VLOOKUP(E32,$A$4:$C$28,3,FALSE) -> 333.96811
E33: 7.25 | F33: 0.30208333 | G33: =VLOOKUP(E33,$A$4:$C$28,3,TRUE)+(MOD(E33,1)*(VLOOKUP(ROUNDDOWN(E33,0)+1,$A$4:$C$28,3,TRUE)-VLOOKUP(ROUNDDOWN(E33,0),$A$4:$C$28,3,TRUE))) -> 378.86477 | H33: =VLOOKUP(E33,$A$4:$C$28,3,FALSE) -> #N/A
E34: 7.5 | F34: 0.3125 | G34: =VLOOKUP(E34,$A$4:$C$28,3,TRUE)+(MOD(E34,1)*(VLOOKUP(ROUNDDOWN(E34,0)+1,$A$4:$C$28,3,TRUE)-VLOOKUP(ROUNDDOWN(E34,0),$A$4:$C$28,3,TRUE))) -> 423.76142 | H34: =VLOOKUP(E34,$A$4:$C$28,3,FALSE) -> #N/A
E35: 7.75 | F35: 0.32291667 | G35: =VLOOKUP(E35,$A$4:$C$28,3,TRUE)+(MOD(E35,1)*(VLOOKUP(ROUNDDOWN(E35,0)+1,$A$4:$C$28,3,TRUE)-VLOOKUP(ROUNDDOWN(E35,0),$A$4:$C$28,3,TRUE))) -> 468.65808 | H35: =VLOOKUP(E35,$A$4:$C$28,3,FALSE) -> #N/A
E36: 8 | F36: 0.33333333 | G36: =VLOOKUP(E36,$A$4:$C$28,3,TRUE)+(MOD(E36,1)*(VLOOKUP(ROUNDDOWN(E36,0)+1,$A$4:$C$28,3,TRUE)-VLOOKUP(ROUNDDOWN(E36,0),$A$4:$C$28,3,TRUE))) -> 513.55474 | H36: =VLOOKUP(E36,$A$4:$C$28,3,FALSE) -> 513.55474
E37: 8.25 | F37: 0.34375 | G37: =VLOOKUP(E37,$A$4:$C$28,3,TRUE)+(MOD(E37,1)*(VLOOKUP(ROUNDDOWN(E37,0)+1,$A$4:$C$28,3,TRUE)-VLOOKUP(ROUNDDOWN(E37,0),$A$4:$C$28,3,TRUE))) -> 526.15731 | H37: =VLOOKUP(E37,$A$4:$C$28,3,FALSE) -> #N/A
E38: 8.5 | F38: 0.35416667 | G38: =VLOOKUP(E38,$A$4:$C$28,3,TRUE)+(MOD(E38,1)*(VLOOKUP(ROUNDDOWN(E38,0)+1,$A$4:$C$28,3,TRUE)-VLOOKUP(ROUNDDOWN(E38,0),$A$4:$C$28,3,TRUE))) -> 538.75988 | H38: =VLOOKUP(E38,$A$4:$C$28,3,FALSE) -> #N/A
E39: 8.75 | F39: 0.36458333 | G39: =VLOOKUP(E39,$A$4:$C$28,3,TRUE)+(MOD(E39,1)*(VLOOKUP(ROUNDDOWN(E39,0)+1,$A$4:$C$28,3,TRUE)-VLOOKUP(ROUNDDOWN(E39,0),$A$4:$C$28,3,TRUE))) -> 551.36245 | H39: =VLOOKUP(E39,$A$4:$C$28,3,FALSE) -> #N/A
E40: 9 | F40: 0.375 | G40: =VLOOKUP(E40,$A$4:$C$28,3,TRUE)+(MOD(E40,1)*(VLOOKUP(ROUNDDOWN(E40,0)+1,$A$4:$C$28,3,TRUE)-VLOOKUP(ROUNDDOWN(E40,0),$A$4:$C$28,3,TRUE))) -> 563.96502 | H40: =VLOOKUP(E40,$A$4:$C$28,3,FALSE) -> 563.96502
... E99: 23.75 | F99: 0.98958333 | G99: =VLOOKUP(E99,$A$4:$C$28,3,TRUE)+(MOD(E99,1)*(VLOOKUP(ROUNDDOWN(E99,0)+1,$A$4:$C$28,3,TRUE)-VLOOKUP(ROUNDDOWN(E99,0),$A$4:$C$28,3,TRUE))) -> 379.65243 | H99: =VLOOKUP(E99,$A$4:$C$28,3,FALSE) -> #N/A

Sheet FFT Uncertainty
A3: Time | B3: Average | C3: 15min | D3: Total | E3: Uncertainty | F3: Contributions
B4: Flow | C4: Volume | D4: Volume | F4: to the
F5: Uncertainty in
B6: (l/s) | C6: (m3) | D6: (m3) | E6: (±%) | F6: TDV (±%)
A7: 0 | B7: =FFT!G4 -> 371.77582 | C7: =SUM(B7*0.9) -> 334.59824 | D7: =SUM(C7) -> 334.59824 | E7: =VLOOKUP(B7,'Data & Results'!$O$6:$P$25,2,TRUE) -> 6.0210548 | F7: =SUM(C7*E7)/$D$104 -> 0.062697182
A8: 0.010416667 | B8: =FFT!G5 -> 362.32389 | C8: =SUM(B8*0.9) -> 326.09151 | D8: =SUM(D7+C8) -> 660.68974 | E8: =VLOOKUP(B8,'Data & Results'!$O$6:$P$25,2,TRUE) -> 6.0210548 | F8: =SUM(C8*E8)/$D$104 -> 0.061103186
A9: 0.020833333 | B9: =FFT!G6 -> 352.87197 | C9: =SUM(B9*0.9) -> 317.58477 | D9: =SUM(D8+C9) -> 978.27452 | E9: =VLOOKUP(B9,'Data & Results'!$O$6:$P$25,2,TRUE) -> 6.0210548 | F9: =SUM(C9*E9)/$D$104 -> 0.05950919
A10: 0.03125 | B10: =FFT!G7 -> 343.42004 | C10: =SUM(B10*0.9) -> 309.07804 | D10: =SUM(D9+C10) -> 1287.3526 | E10: =VLOOKUP(B10,'Data & Results'!$O$6:$P$25,2,TRUE) -> 6.0879848 | F10: =SUM(C10*E10)/$D$104 -> 0.058558978
A11: 0.041666667 | B11: =FFT!G8 -> 333.96811 | C11: =SUM(B11*0.9) -> 300.5713 | D11: =SUM(D10+C11) -> 1587.9239 | E11: =VLOOKUP(B11,'Data & Results'!$O$6:$P$25,2,TRUE) -> 6.0879848 | F11: =SUM(C11*E11)/$D$104 -> 0.056947263
A12: 0.052083333 | B12: =FFT!G9 -> 327.66683 | C12: =SUM(B12*0.9) -> 294.90014 | D12: =SUM(D11+C12) -> 1882.824 | E12: =VLOOKUP(B12,'Data & Results'!$O$6:$P$25,2,TRUE) -> 6.0879848 | F12: =SUM(C12*E12)/$D$104 -> 0.055872787
A13: 0.0625 | B13: =FFT!G10 -> 321.36554 | C13: =SUM(B13*0.9) -> 289.22899 | D13: =SUM(D12+C13) -> 2172.053 | E13: =VLOOKUP(B13,'Data & Results'!$O$6:$P$25,2,TRUE) -> 6.0879848 | F13: =SUM(C13*E13)/$D$104 -> 0.05479831
A14: 0.072916667 | B14: =FFT!G11 -> 315.06426 | C14: =SUM(B14*0.9) -> 283.55783 | D14: =SUM(D13+C14) -> 2455.6108 | E14: =VLOOKUP(B14,'Data & Results'!$O$6:$P$25,2,TRUE) -> 6.1686821 | F14: =SUM(C14*E14)/$D$104 -> 0.054435953
A15: 0.083333333 | B15: =FFT!G12 -> 308.76297 | C15: =SUM(B15*0.9) -> 277.88667 | D15: =SUM(D14+C15) -> 2733.4975 | E15: =VLOOKUP(B15,'Data & Results'!$O$6:$P$25,2,TRUE) -> 6.1686821 | F15: =SUM(C15*E15)/$D$104 -> 0.053347234
A16: 0.09375 | B16: =FFT!G13 -> 287.49613 | C16: =SUM(B16*0.9) -> 258.74652 | D16: =SUM(D15+C16) -> 2992.244 | E16: =VLOOKUP(B16,'Data & Results'!$O$6:$P$25,2,TRUE) -> 6.1686821 | F16: =SUM(C16*E16)/$D$104 -> 0.049672807
A17: 0.10416667 | B17: =FFT!G14 -> 266.2293 | C17: =SUM(B17*0.9) -> 239.60637 | D17: =SUM(D16+C17) -> 3231.8504 | E17: =VLOOKUP(B17,'Data & Results'!$O$6:$P$25,2,TRUE) -> 6.2691957 | F17: =SUM(C17*E17)/$D$104 -> 0.046747885
A18: 0.11458333 | B18: =FFT!G15 -> 244.96246 | C18: =SUM(B18*0.9) -> 220.46621 | D18: =SUM(D17+C18) -> 3452.3166 | E18: =VLOOKUP(B18,'Data & Results'!$O$6:$P$25,2,TRUE) -> 6.3924871 | F18: =SUM(C18*E18)/$D$104 -> 0.043859502
A19: 0.125 | B19: =FFT!G16 -> 223.69562 | C19: =SUM(B19*0.9) -> 201.32606 | D19: =SUM(D18+C19) -> 3653.6426 | E19: =VLOOKUP(B19,'Data & Results'!$O$6:$P$25,2,TRUE) -> 6.5474591 | F19: =SUM(C19*E19)/$D$104 -> 0.041022732
... A102: 0.98958333 | B102: =FFT!G99 -> 379.65243 | C102: =SUM(B102*0.9) -> 341.68719 | D102: =SUM(D101+C102) -> 32132.773 | E102: =VLOOKUP(B102,'Data & Results'!$O$6:$P$25,2,TRUE) -> 6.0210548 | F102: =SUM(C102*E102)/$D$104 -> 0.064025512
D103: Q (m3) | F103: UQ (±%)
C104: Total | D104: =D102 -> 32132.773 | F104: =SUM(F7:F102) -> 6.4289903

Sheet Calculations
A1: h | B1: A | C1: a0 | D1: Cv0(i) | E1: Cv0(ii) | F1: Cv0(iii) | G1: Cv0(iv) | H1: Q0 | I1: (Re/10^5)1 | J1: (del*/L)1a | K1: (del*/L)1b | L1: (del*/L)1 | M1: be1 | N1: he1 | O1: a1 | P1: Cv1(i) | Q1: Cv1(ii) | R1: Cv1(iii) | S1: Cv1(iv) | T1: CD1 | U1: Q1 | V1: (Re/10^5)2 | W1: (del*/L)2a | X1: (del*/L)2b | Y1: (del*/L)2 | Z1: be2 | AA1: he2 | AB1: a2 | AC1: Cv2(I) | AD1: Cv2(ii) | AE1: Cv2(iii) | AF1: Cv2(iv) | AG1: CD2 | AH1: Q2 | AI1: (Re/10^5)3 | AJ1: (del*/L)3a | AK1: (del*/L)3b | AL1: (del*/L)3 | AM1: be3 | AN1: he3 | AO1: a3 | AP1: Cv3(i) | AQ1: Cv3(ii) | AR1: Cv3(iii) | AS1: Cv3(iv) | AT1: CD3 | AU1: Q3 | AW1: Q | AX1: CD | AY1: Cv | AZ1: del*/L | BA1: Re/10^5
